Workbook
Name Causas: Datos!$O$24:$O$38
Name Consolidad_Anual_ingresos: 'CONSOLIDADO REGIONAL (ingresos)'!$A$6:$AL$992
Name Consolidad_Anual_Viveros: 'CONSOLIDADO REGIONAL (ingresos)'!$A$6:$AL$992
Name Consolidad_Anual_Viveros: 'CONSOLIDADO REGIONAL'!$A$6:$AL$2000
Name NOMBRE_DE_VIVERO__CENTRO_DE_ACONDICIONAMIENTO_O_ACOPIO: [1]Hoja1!$E$2:$E$38
Name Resumen_anual2020: 'Reporte Diciembre 2026'!#REF!
Name Resumen_anual2020: 'Reporte Diciembre 2026'!#REF!

Sheet Formato explicativo
C1: FORMATO CONTROL INVENTARIO DE PLANTAS 2026
D4: INVENTARIO INICIAL | K4: MARZO | W4: JUNIO | AI4: SEPTIEMBRE | AU4: DICIEMBRE
C5: Ítems | D5: Antecedentes del vivero | E5: Antecedentes de la especie | F5: Total Plantas Enero | G5: Valores | J5: Ítems | K5: Antecedentes del vivero | L5: Antecedentes de la especie | M5: Total Plantas enero | N5: N° Plantas Ingresadas | O5: Entregas | P5: Movimientos internos | Q5: Traslados | R5: Bajas | S5: Total Plantas Marzo | T5: Valores | V5: Ítems | W5: Antecedentes del vivero | X5: Antecedentes de la especie | Y5: Total Plantas Marzo | Z5: N° Plantas Ingresadas | AA5: Entregas | AB5: Movimientos internos | AC5: Traslados | AD5: Bajas | AE5: Total Plantas Junio | AF5: Valores | AH5: Ítems | AI5: Antecedentes del vivero | AJ5: Antecedentes de la especie | AK5: Total Plantas Junio | AL5: N° Plantas Ingresadas | AM5: Entregas | AN5: Movimientos internos | AO5: Traslados | AP5: Bajas | AQ5: Total Plantas Septiembre | AR5: Valores | AT5: Ítems | AU5: Antecedentes del vivero | AV5: Antecedentes de la especie | AW5: Total Plantas Septiembre | AX5: N° Plantas Ingresadas | AY5: Entregas | AZ5: Movimientos internos | BA5: Traslados | BB5: Bajas | BC5: Total Plantas Diciembre | BD5: Valores | BF5: INFORME DE INGRESOS PLANTAS A INVENTARIO | BJ5: INFORME DE SALIDA,N° PLANTAS SEGÚN DESTINO, | BR5: INFORME DE INGRESOS PLANTAS A INVENTARIO | CA5: INFORME RESUMEN STOCK
B6: Fila 6 | C6: Inventario | D6: INVENTARIO 1 (Modificar) | F6: E | G6: $ | I6: Fila 6 | J6: Inventario | K6: INVENTARIO 1 (no modificar) | M6: E | N6: 0 | O6: X | P6: X | Q6: X | R6: X | S6: M | T6: $ | U6: Fila 6 | V6: Inventario | W6: INVENTARIO 1 (no modificar) | Y6: M | Z6: 0 | AA6: X | AB6: X | AC6: X | AD6: X | AE6: J | AF6: $ | AG6: Fila 6 | AH6: Inventario | AI6: INVENTARIO 1 (no modificar) | AK6: J | AL6: 0 | AM6: X | AN6: X | AO6: X | AP6: X | AQ6: S | AR6: $ | AS6: Fila 6 | AT6: Inventario | AU6: INVENTARIO 1 (no modificar) | AW6: S | AX6: 0 | AY6: X | AZ6: X | BA6: X | BB6: X | BC6: D | BD6: $ | BF6: MES | BG6: FUENTE DE ABASTECIMIENTO | BH6: N° PLANTAS | BJ6: VIVEROS | BK6: MES | BL6: DIFUSION | BM6: PROGRAMAS | BN6: TRASLADOS | BR6: VIVERO | BS6: FECHA | BT6: ESPECIES | BU6: ORIGEN | BV6: RANGO DE ALTURA | BW6: CONTENEDOR | BX6: VALOR | BY6: N° PLANTAS DE BAJA | CA6: MES | CB6: FUENTE DE ABASTECIMIENTO | CC6: N° PLANTAS
B7: Fila 7 | C7: Inventario | F7: E | G7: $ | I7: Fila 7 | J7: Inventario | M7: E | N7: 0 | O7: X | P7: X | Q7: X | R7: X | S7: M | T7: $ | U7: Fila 7 | V7: Inventario | Y7: M | Z7: 0 | AA7: X | AB7: X | AC7: X | AD7: X | AE7: J | AF7: $ | AG7: Fila 7 | AH7: Inventario | AK7: J | AL7: 0 | AM7: X | AN7: X | AO7: X | AP7: X | AQ7: S | AR7: $ | AS7: Fila 7 | AT7: Inventario | AW7: S | AX7: 0 | AY7: X | AZ7: X | BA7: X | BB7: X | BC7: D | BD7: $
B8: Fila 8 | C8: Inventario | F8: E | G8: $ | I8: Fila 8 | J8: Inventario | M8: E | N8: 0 | O8: X | P8: X | Q8: X | R8: X | S8: M | T8: $ | U8: Fila 8 | V8: Inventario | Y8: M | Z8: 0 | AA8: X | AB8: X | AC8: X | AD8: X | AE8: J | AF8: $ | AG8: Fila 8 | AH8: Inventario | AK8: J | AL8: 0 | AM8: X | AN8: X | AO8: X | AP8: X | AQ8: S | AR8: $ | AS8: Fila 8 | AT8: Inventario | AW8: S | AX8: 0 | AY8: X | AZ8: X | BA8: X | BB8: X | BC8: D | BD8: $ | BF8: MARZO | BG8: PRODUCCIÓN PROPIA | BH8: X | BJ8: XXX | BK8: MARZO | BL8: X | BM8: X | BN8: X | BR8: X | BS8: XX/XX/XXX | BT8: X | BU8: X | BV8: X | BW8: X | BX8: X | BY8: X | CA8: MARZO | CB8: PRODUCCIÓN PROPIA
B9: Fila 9 | C9: Inventario | F9: E | G9: $ | I9: Fila 9 | J9: Inventario | M9: E | N9: 0 | O9: X | P9: X | Q9: X | R9: X | S9: M | T9: $ | U9: Fila 9 | V9: Inventario | Y9: M | Z9: 0 | AA9: X | AB9: X | AC9: X | AD9: X | AE9: J | AF9: $ | AG9: Fila 9 | AH9: Inventario | AK9: J | AL9: 0 | AM9: X | AN9: X | AO9: X | AP9: X | AQ9: S | AR9: $ | AS9: Fila 9 | AT9: Inventario | AW9: S | AX9: 0 | AY9: X | AZ9: X | BA9: X | BB9: X | BC9: D | BD9: $ | BR9: X
B10: Fila 10 | C10: Inventario | F10: E | G10: $ | I10: Fila 10 | J10: Inventario | M10: E | N10: 0 | O10: X | P10: X | Q10: X | R10: X | S10: M | T10: $ | U10: Fila 10 | V10: Inventario | Y10: M | Z10: 0 | AA10: X | AB10: X | AC10: X | AD10: X | AE10: J | AF10: $ | AG10: Fila 10 | AH10: Inventario | AK10: J | AL10: 0 | AM10: X | AN10: X | AO10: X | AP10: X | AQ10: S | AR10: $ | AS10: Fila 10 | AT10: Inventario | AW10: S | AX10: 0 | AY10: X | AZ10: X | BA10: X | BB10: X | BC10: D | BD10: $ | BF10: JUNIO | BG10: COMPRAS | BH10: X | BJ10: XXX | BK10: JUNIO | BL10: X | BM10: X | BN10: X | BR10: X | BS10: XX/XX/XXX | BT10: X | BU10: X | BV10: X | BW10: X | BX10: X | BY10: X | CA10: JUNIO | CB10: COMPRAS
B11: Fila 11 | C11: Inventario | F11: E | G11: $ | I11: Fila 11 | J11: Inventario | M11: E | N11: 0 | O11: X | P11: X | Q11: X | R11: X | S11: M | T11: $ | U11: Fila 11 | V11: Inventario | Y11: M | Z11: 0 | AA11: X | AB11: X | AC11: X | AD11: X | AE11: J | AF11: $ | AG11: Fila 11 | AH11: Inventario | AK11: J | AL11: 0 | AM11: X | AN11: X | AO11: X | AP11: X | AQ11: S | AR11: $ | AS11: Fila 11 | AT11: Inventario | AW11: S | AX11: 0 | AY11: X | AZ11: X | BA11: X | BB11: X | BC11: D | BD11: $ | BR11: X
B12: Fila 12 | C12: Inventario | F12: E | G12: $ | I12: Fila 12 | J12: Inventario | M12: E | N12: 0 | O12: X | P12: X | Q12: X | R12: X | S12: M | T12: $ | U12: Fila 12 | V12: Inventario | Y12: M | Z12: 0 | AA12: X | AB12: X | AC12: X | AD12: X | AE12: J | AF12: $ | AG12: Fila 12 | AH12: Inventario | AK12: J | AL12: 0 | AM12: X | AN12: X | AO12: X | AP12: X | AQ12: S | AR12: $ | AS12: Fila 12 | AT12: Inventario | AW12: S | AX12: 0 | AY12: X | AZ12: X | BA12: X | BB12: X | BC12: D | BD12: $ | BF12: SEPTIEMBRE | BG12: DONACIONES | BH12: X | BJ12: XXX | BK12: SEPTIEMBRE | BL12: X | BM12: X | BN12: X | BR12: X | BS12: XX/XX/XXX | BT12: X | BU12: X | BV12: X | BW12: X | BX12: X | BY12: X | CA12: SEPTIEMBRE | CB12: DONACIONES
C13: Total | F13: E | G13: $ | I13: Fila 13 | J13: Ingreso (M) | K13: MMM | L13: MM | M13: 0 | N13: X | O13: X | P13: X | Q13: X | R13: X | S13: M | T13: $ | U13: Fila 13 | V13: Ingreso (M) | W13: MMM | X13: MM | Y13: M | Z13: 0 | AA13: X | AB13: X | AC13: X | AD13: X | AE13: J | AF13: $ | AG13: Fila 13 | AH13: Ingreso (M) | AI13: MMM | AJ13: MM | AK13: J | AL13: 0 | AM13: X | AN13: X | AO13: X | AP13: X | AQ13: S | AR13: $ | AS13: Fila 13 | AT13: Ingreso (M) | AU13: MMM | AV13: MM | AW13: S | AX13: 0 | AY13: X | AZ13: X | BA13: X | BB13: X | BC13: D | BD13: $ | BR13: X
I14: Fila 14 | J14: Ingreso (M) | K14: MMM | L14: MM | M14: 0 | N14: X | O14: X | P14: X | Q14: X | R14: X | S14: M | T14: $ | U14: Fila 14 | V14: Ingreso (M) | W14: MMM | X14: MM | Y14: M | Z14: 0 | AA14: X | AB14: X | AC14: X | AD14: X | AE14: J | AF14: $ | AG14: Fila 14 | AH14: Ingreso (M) | AI14: MMM | AJ14: MM | AK14: J | AL14: 0 | AM14: X | AN14: X | AO14: X | AP14: X | AQ14: S | AR14: $ | AS14: Fila 14 | AT14: Ingreso (M) | AU14: MMM | AV14: MM | AW14: S | AX14: 0 | AY14: X | AZ14: X | BA14: X | BB14: X | BC14: D | BD14: $ | BF14: DICIEMBRE | BJ14: XX | BK14: DICIEMBRE | BL14: X | BM14: X | BN14: X | BR14: X | BS14: XX/XX/XXX | BT14: X | BU14: X | BV14: X | BW14: X | BX14: X | BY14: X | CA14: DICIEMBRE
D15: HOJA 2 | I15: Fila 15 | J15: Ingreso (M) | K15: MMM | L15: MM | M15: 0 | N15: X | O15: X | P15: X | Q15: X | R15: X | S15: M | T15: $ | U15: Fila 15 | V15: Ingreso (M) | W15: MMM | X15: MM | Y15: M | Z15: 0 | AA15: X | AB15: X | AC15: X | AD15: X | AE15: J | AF15: $ | AG15: Fila 15 | AH15: Ingreso (M) | AI15: MMM | AJ15: MM | AK15: J | AL15: 0 | AM15: X | AN15: X | AO15: X | AP15: X | AQ15: S | AR15: $ | AS15: Fila 15 | AT15: Ingreso (M) | AU15: MMM | AV15: MM | AW15: S | AX15: 0 | AY15: X | AZ15: X | BA15: X | BB15: X | BC15: D | BD15: $
I16: Fila 16 | J16: Ingresos | M16: 0 | U16: Fila 16 | V16: Ingresos (J) | W16: JJJ | X16: JJJ | Y16: 0 | Z16: X | AA16: X | AB16: X | AC16: X | AD16: X | AE16: J | AF16: $ | AG16: Fila 16 | AH16: Ingresos (J) | AI16: JJJ | AJ16: JJJ | AK16: J | AL16: 0 | AM16: X | AN16: X | AO16: X | AP16: X | AQ16: S | AR16: $ | AS16: Fila 16 | AT16: Ingresos (J) | AU16: JJJ | AV16: JJJ | AW16: S | AX16: 0 | AY16: X | AZ16: X | BA16: X | BB16: X | BC16: D | BD16: $ | BG16: TOTAL | BH16: XX | BK16: TOTAL | BL16: XX | BM16: XX | BN16: XX | BT16: TOTAL | BU16: XX | BV16: XX | BW16: XX | BY16: XX
I17: Fila 17 | J17: Ingresos | M17: 0 | U17: Fila 17 | AE17: 0 | AF17: $ | AG17: Fila 17 | AH17: Ingresos (S) | AI17: SSS | AJ17: SSS | AK17: 0 | AL17: X | AM17: X | AN17: X | AO17: X | AP17: X | AQ17: S | AR17: $ | AS17: Fila 17 | AT17: Ingresos (S) | AU17: SSS | AV17: SSS | AW17: S | AX17: 0 | AY17: X | AZ17: X | BA17: X | BB17: X | BC17: D | BD17: $
I18: Fila 18 | J18: Ingresos | M18: 0 | U18: Fila 18 | AE18: 0 | AF18: $ | AG18: Fila 18 | AK18: 0 | AQ18: 0 | AR18: $ | AS18: Fila 18 | AT18: Ingresos (D) | AU18: DDD | AV18: DDD | AW18: 0 | AX18: X | AY18: X | AZ18: X | BA18: X | BB18: X | BC18: D | BD18: $
I19: Fila 19 | J19: Ingresos | M19: 0 | U19: Fila 19 | AE19: 0 | AF19: $ | AG19: Fila 19 | AK19: 0 | AQ19: 0 | AR19: $ | AS19: Fila 19 | AW19: 0 | BC19: 0 | BD19: $
J20: Total | M20: E | N20: X | O20: X | P20: X | Q20: X | R20: X | S20: M | T20: $ | V20: Total | Y20: M | Z20: X | AA20: X | AB20: X | AC20: X | AD20: X | AE20: J | AF20: $ | AH20: Total | AK20: J | AL20: X | AM20: X | AN20: X | AO20: X | AP20: X | AQ20: S | AR20: $ | AT20: Total | AW20: S | AX20: X | AY20: X | AZ20: X | BA20: X | BB20: X | BC20: D | BD20: $
M22: HOJA 3 | Y22: HOJA 4 | AK22: HOJA 5 | AW22: HOJA 6
C24: Observaciones
C25: 1 | D25: En la hoja Inventario Inicial: sólo registrar la información del inventario de diciembre 2025, que debe ser el mismo.
C26: 2 | D26: En la hoja Inventario Inicial, AL LLENARLA , los valores se copian en forma automática en todos los reportes de los trimestres posteriores.
C27: 3 | D27: La columna "Total" de la hoja Inventario Inicial, se repite en la hoja Reporte Marzo 2026. A esta columna se le descuentan las salidas, dando como resultado el "Total de Plantas Marzo".
C28: 4 | D28: La columna "Total Plantas Marzo" se repite en hoja Reporte Junio 2026 y lo mismo sucede con los otros reportes.
C29: 5 | D29: Es obligación llenar todas las filas (INGRESOS DEL AÑO) de forma ordenada en la hoja Inventario Inicial, pues como se explicó, estas se repiten en las otras. hojas.
C30: 6 | D30: No se pueden modificar la zona de "Inventario Marzo, Junio, Septiembre o Diciembre".
C31: 7 | D31: La zona con "X" corresponde al lugar donde se registran las salidas (entregas, traslados y bajas) (Formato explicativo).
C32: 8 | D32: Se pueden realizar nuevos ingresos sólo a partir de la hoja Inventario Marzo 2026.
C33: 9 | D33: El número de plantas ingresadas, solo registrarlas en la intersección columna X fila de ingresos (X).
C34: 10 | D34: El orden para registrar los nuevos ingresos es: primero todos los ingresos de marzo, después los ingreso de junio hasta diciembre, ya que no se puede ingresar valores de marzo, teniendo completadas las mismas filas de junio, igual en los otros reportes (ver formato explicativo).
C36: 11 | D36: Los ingresos deben hacerse en las fechas correspondiente y no después (Si es trimestre Reporte Marzo, no puede ser en Reporte de Junio, hay que seguir ese orden).
C37: 12 | D37: Para insertar una fila nueva, posicionarse en la barra numérica al lado de la columna, apretar el botón derecho del mouse, después insertar bajo esta como "insertar celdas copiadas", tantas veces como sea necesario.(Hacerlo en Marzo para arrastrar los totales).
... C43: 16 | D43: NO BORRAR NINGUNA FILA, SOLO OCULTARLAS
C46: Para actualizar las planillas y tablas dinámicas, después de hacer modificaciones, ir al menu parte superior, hacer clic en Datos y elegir "actualizar todo."

Sheet INVENTARIO INICIAL
B1: Control Inventario de Plantas SIGI GBCC 8 | 2026
B2: Viveros, centros de acopio y acondicionamiento CONAF
B3: Inventario Diciembre 2025
A5: ANTECEDENTES DEL VIVERO | H5: ANTECEDENTES DE LA ESPECIE | T5: VALORIZACIÓN | V5: Observaciones | X5: Código de planta para Guía de Despacho
A6: Items | B6: Unidad Productiva | C6: Unidad Administrativa | D6: Provincia | E6: Comuna | F6: Nombre del Encargado | G6: Teléfono de Contacto | H6: Nombre Científico | I6: Nombre Común | J6: Origen | K6: Fuente de Abastecimiento | L6: Destino de la Planta | M6: Tipo de Reproducción | N6: Tipo de Contenedor | O6: Fecha Ingreso a Inventario (Día-Mes-Año) | P6: Tiempo de Viverización (años) | Q6: Rango de Altura | R6: Sectores del Vivero | S6: N° Total Plantas Control Inventario Diciembre 2025 | T6: Valor Neto ($) por Planta | U6: Valor Total ($) por Lote
A7: Inventario | C7: =IF(B7=0,"",VLOOKUP(B7,Datos!$H$2:$K$39,2,FALSE)) | D7: =IF(B7=0,"",VLOOKUP(B7,Datos!$H$2:$K$39,3,FALSE)) | E7: =IF(B7=0,"",VLOOKUP(B7,Datos!$H$2:$K$39,4,FALSE)) | I7: =IF(H7=0,"",VLOOKUP(H7,Datos!$B$2:$D$891,2,FALSE)) | J7: =IF(H7=0,"",VLOOKUP(H7,Datos!$B$2:$D$891,3,FALSE)) | U7: =S7*T7 -> 0
A8: Inventario | C8: =IF(B8=0,"",VLOOKUP(B8,Datos!$H$2:$K$39,2,FALSE)) | D8: =IF(B8=0,"",VLOOKUP(B8,Datos!$H$2:$K$39,3,FALSE)) | E8: =IF(B8=0,"",VLOOKUP(B8,Datos!$H$2:$K$39,4,FALSE)) | I8: =IF(H8=0,"",VLOOKUP(H8,Datos!$B$2:$D$891,2,FALSE)) | J8: =IF(H8=0,"",VLOOKUP(H8,Datos!$B$2:$D$891,3,FALSE)) | U8: =S8*T8 -> 0
A9: Inventario | C9: =IF(B9=0,"",VLOOKUP(B9,Datos!$H$2:$K$39,2,FALSE)) | D9: =IF(B9=0,"",VLOOKUP(B9,Datos!$H$2:$K$39,3,FALSE)) | E9: =IF(B9=0,"",VLOOKUP(B9,Datos!$H$2:$K$39,4,FALSE)) | I9: =IF(H9=0,"",VLOOKUP(H9,Datos!$B$2:$D$891,2,FALSE)) | J9: =IF(H9=0,"",VLOOKUP(H9,Datos!$B$2:$D$891,3,FALSE)) | U9: =S9*T9 -> 0
A10: Inventario | C10: =IF(B10=0,"",VLOOKUP(B10,Datos!$H$2:$K$39,2,FALSE)) | D10: =IF(B10=0,"",VLOOKUP(B10,Datos!$H$2:$K$39,3,FALSE)) | E10: =IF(B10=0,"",VLOOKUP(B10,Datos!$H$2:$K$39,4,FALSE)) | I10: =IF(H10=0,"",VLOOKUP(H10,Datos!$B$2:$D$891,2,FALSE)) | J10: =IF(H10=0,"",VLOOKUP(H10,Datos!$B$2:$D$891,3,FALSE)) | U10: =S10*T10 -> 0
A11: Inventario | C11: =IF(B11=0,"",VLOOKUP(B11,Datos!$H$2:$K$39,2,FALSE)) | D11: =IF(B11=0,"",VLOOKUP(B11,Datos!$H$2:$K$39,3,FALSE)) | E11: =IF(B11=0,"",VLOOKUP(B11,Datos!$H$2:$K$39,4,FALSE)) | I11: =IF(H11=0,"",VLOOKUP(H11,Datos!$B$2:$D$891,2,FALSE)) | J11: =IF(H11=0,"",VLOOKUP(H11,Datos!$B$2:$D$891,3,FALSE)) | U11: =S11*T11 -> 0
A12: Inventario | C12: =IF(B12=0,"",VLOOKUP(B12,Datos!$H$2:$K$39,2,FALSE)) | D12: =IF(B12=0,"",VLOOKUP(B12,Datos!$H$2:$K$39,3,FALSE)) | E12: =IF(B12=0,"",VLOOKUP(B12,Datos!$H$2:$K$39,4,FALSE)) | I12: =IF(H12=0,"",VLOOKUP(H12,Datos!$B$2:$D$891,2,FALSE)) | J12: =IF(H12=0,"",VLOOKUP(H12,Datos!$B$2:$D$891,3,FALSE)) | U12: =S12*T12 -> 0
A13: Inventario | C13: =IF(B13=0,"",VLOOKUP(B13,Datos!$H$2:$K$39,2,FALSE)) | D13: =IF(B13=0,"",VLOOKUP(B13,Datos!$H$2:$K$39,3,FALSE)) | E13: =IF(B13=0,"",VLOOKUP(B13,Datos!$H$2:$K$39,4,FALSE)) | I13: =IF(H13=0,"",VLOOKUP(H13,Datos!$B$2:$D$891,2,FALSE)) | J13: =IF(H13=0,"",VLOOKUP(H13,Datos!$B$2:$D$891,3,FALSE)) | U13: =S13*T13 -> 0
A14: Inventario | C14: =IF(B14=0,"",VLOOKUP(B14,Datos!$H$2:$K$39,2,FALSE)) | D14: =IF(B14=0,"",VLOOKUP(B14,Datos!$H$2:$K$39,3,FALSE)) | E14: =IF(B14=0,"",VLOOKUP(B14,Datos!$H$2:$K$39,4,FALSE)) | I14: =IF(H14=0,"",VLOOKUP(H14,Datos!$B$2:$D$891,2,FALSE)) | J14: =IF(H14=0,"",VLOOKUP(H14,Datos!$B$2:$D$891,3,FALSE)) | U14: =S14*T14 -> 0
A15: Inventario | C15: =IF(B15=0,"",VLOOKUP(B15,Datos!$H$2:$K$39,2,FALSE)) | D15: =IF(B15=0,"",VLOOKUP(B15,Datos!$H$2:$K$39,3,FALSE)) | E15: =IF(B15=0,"",VLOOKUP(B15,Datos!$H$2:$K$39,4,FALSE)) | I15: =IF(H15=0,"",VLOOKUP(H15,Datos!$B$2:$D$891,2,FALSE)) | J15: =IF(H15=0,"",VLOOKUP(H15,Datos!$B$2:$D$891,3,FALSE)) | U15: =S15*T15 -> 0
A16: Inventario | C16: =IF(B16=0,"",VLOOKUP(B16,Datos!$H$2:$K$39,2,FALSE)) | D16: =IF(B16=0,"",VLOOKUP(B16,Datos!$H$2:$K$39,3,FALSE)) | E16: =IF(B16=0,"",VLOOKUP(B16,Datos!$H$2:$K$39,4,FALSE)) | I16: =IF(H16=0,"",VLOOKUP(H16,Datos!$B$2:$D$891,2,FALSE)) | J16: =IF(H16=0,"",VLOOKUP(H16,Datos!$B$2:$D$891,3,FALSE)) | U16: =S16*T16 -> 0
A17: Inventario | C17: =IF(B17=0,"",VLOOKUP(B17,Datos!$H$2:$K$39,2,FALSE)) | D17: =IF(B17=0,"",VLOOKUP(B17,Datos!$H$2:$K$39,3,FALSE)) | E17: =IF(B17=0,"",VLOOKUP(B17,Datos!$H$2:$K$39,4,FALSE)) | I17: =IF(H17=0,"",VLOOKUP(H17,Datos!$B$2:$D$891,2,FALSE)) | J17: =IF(H17=0,"",VLOOKUP(H17,Datos!$B$2:$D$891,3,FALSE)) | U17: =S17*T17 -> 0
A18: Inventario | C18: =IF(B18=0,"",VLOOKUP(B18,Datos!$H$2:$K$39,2,FALSE)) | D18: =IF(B18=0,"",VLOOKUP(B18,Datos!$H$2:$K$39,3,FALSE)) | E18: =IF(B18=0,"",VLOOKUP(B18,Datos!$H$2:$K$39,4,FALSE)) | I18: =IF(H18=0,"",VLOOKUP(H18,Datos!$B$2:$D$891,2,FALSE)) | J18: =IF(H18=0,"",VLOOKUP(H18,Datos!$B$2:$D$891,3,FALSE)) | U18: =S18*T18 -> 0
... A360: Inventario | C360: =IF(B360=0,"",VLOOKUP(B360,Datos!$H$2:$K$39,2,FALSE)) | D360: =IF(B360=0,"",VLOOKUP(B360,Datos!$H$2:$K$39,3,FALSE)) | E360: =IF(B360=0,"",VLOOKUP(B360,Datos!$H$2:$K$39,4,FALSE)) | I360: =IF(H360=0,"",VLOOKUP(H360,Datos!$B$2:$D$891,2,FALSE)) | J360: =IF(H360=0,"",VLOOKUP(H360,Datos!$B$2:$D$891,3,FALSE)) | U360: =S360*T360 -> 0
A361: TOTAL | S361: =SUM(S7:S360) -> 0 | U361: =SUM(U7:U360) -> 0

Sheet Reporte Marzo 2026
B1: Control Inventario de Plantas SIGI GBCC 8 | 2026
B2: Viveros, centros de acopio y acondicionamiento CONAF
B3: Reporte Marzo 2026
T4: INGRESOS Y EGRESOS DE PLANTAS EN EL PRIMER TRIMESTRE (ENERO A MARZO)
A5: ANTECEDENTES DEL VIVERO | H5: ANTECEDENTES DE LA ESPECIE | T5: N° DE PLANTAS NUEVAS | U5: N° DE PLANTAS ENTREGADAS Y/O VENDIDAS | X5: Movimientos Internos (Cambios Rango de Altura o Contenedor) | Y5: TRASLADOS INTERNOS A OTRAS UNIDADES CONAF | AB5: BAJA DE PLANTAS DE INVENTARIO | AF5: STOCK | AG5: VALORIZACIÓN
A6: Ítems | B6: Unidad Productiva | C6: Unidad Administrativa | D6: Provincia | E6: Comuna | F6: Nombre del Encargado | G6: Teléfono de Contacto | H6: Nombre Científico | I6: Nombre Común | J6: Origen | K6: Fuente de Abastecimiento | L6: Destino de la Planta | M6: Tipo de Reproducción | N6: Tipo de Contenedor | O6: Fecha Ingreso a Inventario (Día-Mes-Año) | P6: Tiempo de Viverización (años) | Q6: Rango de Altura | R6: Sectores del Vivero | S6: N° Total Plantas Control Inventario Diciembre 2025 | T6: N° Plantas NUEVAS Ingresadas a Inventario | U6: N° Entregas por Difusión | V6: N° Entregas a Programas | W6: N° Plantas Venta | X6: N° Plantas (M.I.) | Y6: N° Plantas Trasladadas | Z6: Unidades Recepción de Traslado | AA6: N° de Documento, Factura o Guía de Despacho | AB6: N° Plantas de Baja | AC6: Causas | AD6: N° Resolución | AE6: Fecha de Resolución | AF6: N° TOTAL DE PLANTAS INVENTARIO MARZO 2026 | AG6: Valor Neto ($) por Planta | AH6: Valor Total ($) por Lote | AI6: Ingresos e Inventario Inicial | AJ6: Egresos | AK6: stock Marzo | AL6: MES REPORTE | AN6: Código de planta para Guía de Despacho
A7: ='INVENTARIO INICIAL'!A7 -> Inventario | B7: ='INVENTARIO INICIAL'!B7 -> 0 | C7: =IF(B7=0,"",VLOOKUP(B7,Datos!$H$2:$K$39,2,FALSE)) | D7: =IF(B7=0,"",VLOOKUP(B7,Datos!$H$2:$K$39,3,FALSE)) | E7: =IF(B7=0,"",VLOOKUP(B7,Datos!$H$2:$K$39,4,FALSE)) | F7: ='INVENTARIO INICIAL'!F7 -> 0 | G7: ='INVENTARIO INICIAL'!G7 -> 0 | H7: ='INVENTARIO INICIAL'!H7 -> 0 | I7: =IF(H7=0,"",VLOOKUP(H7,Datos!$B$2:$D$908,2,FALSE)) | J7: =IF(H7=0,"",VLOOKUP(H7,Datos!$B$2:$D$908,3,FALSE)) | K7: ='INVENTARIO INICIAL'!K7 -> 0 | L7: ='INVENTARIO INICIAL'!L7 -> 0 | M7: ='INVENTARIO INICIAL'!M7 -> 0 | N7: ='INVENTARIO INICIAL'!N7 -> 0 | O7: ='INVENTARIO INICIAL'!O7 -> 0 | P7: ='INVENTARIO INICIAL'!P7 -> 0 | Q7: ='INVENTARIO INICIAL'!Q7 -> 0 | R7: ='INVENTARIO INICIAL'!R7 -> 0 | S7: ='INVENTARIO INICIAL'!S7 -> 0 | AF7: =IF(AI7>=AJ7,IF(AK7>=0,IF(AJ7>=0,AK7,"Error"))) -> 0 | AG7: ='INVENTARIO INICIAL'!T7 -> 0 | AH7: =AF7*AG7 -> 0 | AI7: =S7+T7 -> 0 | AJ7: =U7+V7+W7+X7+Y7+AB7 -> 0 | AK7: =AI7-AJ7 -> 0 | AL7: Marzo | AN7: ='INVENTARIO INICIAL'!X7 -> 0
A8: ='INVENTARIO INICIAL'!A8 -> Inventario | B8: ='INVENTARIO INICIAL'!B8 -> 0 | C8: =IF(B8=0,"",VLOOKUP(B8,Datos!$H$2:$K$39,2,FALSE)) | D8: =IF(B8=0,"",VLOOKUP(B8,Datos!$H$2:$K$39,3,FALSE)) | E8: =IF(B8=0,"",VLOOKUP(B8,Datos!$H$2:$K$39,4,FALSE)) | F8: ='INVENTARIO INICIAL'!F8 -> 0 | G8: ='INVENTARIO INICIAL'!G8 -> 0 | H8: ='INVENTARIO INICIAL'!H8 -> 0 | I8: =IF(H8=0,"",VLOOKUP(H8,Datos!$B$2:$D$908,2,FALSE)) | J8: =IF(H8=0,"",VLOOKUP(H8,Datos!$B$2:$D$908,3,FALSE)) | K8: ='INVENTARIO INICIAL'!K8 -> 0 | L8: ='INVENTARIO INICIAL'!L8 -> 0 | M8: ='INVENTARIO INICIAL'!M8 -> 0 | N8: ='INVENTARIO INICIAL'!N8 -> 0 | O8: ='INVENTARIO INICIAL'!O8 -> 0 | P8: ='INVENTARIO INICIAL'!P8 -> 0 | Q8: ='INVENTARIO INICIAL'!Q8 -> 0 | R8: ='INVENTARIO INICIAL'!R8 -> 0 | S8: ='INVENTARIO INICIAL'!S8 -> 0 | AF8: =IF(AI8>=AJ8,IF(AK8>=0,IF(AJ8>=0,AK8,"Error"))) -> 0 | AG8: ='INVENTARIO INICIAL'!T8 -> 0 | AH8: =AF8*AG8 -> 0 | AI8: =S8+T8 -> 0 | AJ8: =U8+V8+W8+X8+Y8+AB8 -> 0 | AK8: =AI8-AJ8 -> 0 | AL8: Marzo | AN8: ='INVENTARIO INICIAL'!X8 -> 0
A9: ='INVENTARIO INICIAL'!A9 -> Inventario | B9: ='INVENTARIO INICIAL'!B9 -> 0 | C9: =IF(B9=0,"",VLOOKUP(B9,Datos!$H$2:$K$39,2,FALSE)) | D9: =IF(B9=0,"",VLOOKUP(B9,Datos!$H$2:$K$39,3,FALSE)) | E9: =IF(B9=0,"",VLOOKUP(B9,Datos!$H$2:$K$39,4,FALSE)) | F9: ='INVENTARIO INICIAL'!F9 -> 0 | G9: ='INVENTARIO INICIAL'!G9 -> 0 | H9: ='INVENTARIO INICIAL'!H9 -> 0 | I9: =IF(H9=0,"",VLOOKUP(H9,Datos!$B$2:$D$908,2,FALSE)) | J9: =IF(H9=0,"",VLOOKUP(H9,Datos!$B$2:$D$908,3,FALSE)) | K9: ='INVENTARIO INICIAL'!K9 -> 0 | L9: ='INVENTARIO INICIAL'!L9 -> 0 | M9: ='INVENTARIO INICIAL'!M9 -> 0 | N9: ='INVENTARIO INICIAL'!N9 -> 0 | O9: ='INVENTARIO INICIAL'!O9 -> 0 | P9: ='INVENTARIO INICIAL'!P9 -> 0 | Q9: ='INVENTARIO INICIAL'!Q9 -> 0 | R9: ='INVENTARIO INICIAL'!R9 -> 0 | S9: ='INVENTARIO INICIAL'!S9 -> 0 | AF9: =IF(AI9>=AJ9,IF(AK9>=0,IF(AJ9>=0,AK9,"Error"))) -> 0 | AG9: ='INVENTARIO INICIAL'!T9 -> 0 | AH9: =AF9*AG9 -> 0 | AI9: =S9+T9 -> 0 | AJ9: =U9+V9+W9+X9+Y9+AB9 -> 0 | AK9: =AI9-AJ9 -> 0 | AL9: Marzo | AN9: ='INVENTARIO INICIAL'!X9 -> 0
A10: ='INVENTARIO INICIAL'!A10 -> Inventario | B10: ='INVENTARIO INICIAL'!B10 -> 0 | C10: =IF(B10=0,"",VLOOKUP(B10,Datos!$H$2:$K$39,2,FALSE)) | D10: =IF(B10=0,"",VLOOKUP(B10,Datos!$H$2:$K$39,3,FALSE)) | E10: =IF(B10=0,"",VLOOKUP(B10,Datos!$H$2:$K$39,4,FALSE)) | F10: ='INVENTARIO INICIAL'!F10 -> 0 | G10: ='INVENTARIO INICIAL'!G10 -> 0 | H10: ='INVENTARIO INICIAL'!H10 -> 0 | I10: =IF(H10=0,"",VLOOKUP(H10,Datos!$B$2:$D$908,2,FALSE)) | J10: =IF(H10=0,"",VLOOKUP(H10,Datos!$B$2:$D$908,3,FALSE)) | K10: ='INVENTARIO INICIAL'!K10 -> 0 | L10: ='INVENTARIO INICIAL'!L10 -> 0 | M10: ='INVENTARIO INICIAL'!M10 -> 0 | N10: ='INVENTARIO INICIAL'!N10 -> 0 | O10: ='INVENTARIO INICIAL'!O10 -> 0 | P10: ='INVENTARIO INICIAL'!P10 -> 0 | Q10: ='INVENTARIO INICIAL'!Q10 -> 0 | R10: ='INVENTARIO INICIAL'!R10 -> 0 | S10: ='INVENTARIO INICIAL'!S10 -> 0 | AF10: =IF(AI10>=AJ10,IF(AK10>=0,IF(AJ10>=0,AK10,"Error"))) -> 0 | AG10: ='INVENTARIO INICIAL'!T10 -> 0 | AH10: =AF10*AG10 -> 0 | AI10: =S10+T10 -> 0 | AJ10: =U10+V10+W10+X10+Y10+AB10 -> 0 | AK10: =AI10-AJ10 -> 0 | AL10: Marzo | AN10: ='INVENTARIO INICIAL'!X10 -> 0
A11: ='INVENTARIO INICIAL'!A11 -> Inventario | B11: ='INVENTARIO INICIAL'!B11 -> 0 | C11: =IF(B11=0,"",VLOOKUP(B11,Datos!$H$2:$K$39,2,FALSE)) | D11: =IF(B11=0,"",VLOOKUP(B11,Datos!$H$2:$K$39,3,FALSE)) | E11: =IF(B11=0,"",VLOOKUP(B11,Datos!$H$2:$K$39,4,FALSE)) | F11: ='INVENTARIO INICIAL'!F11 -> 0 | G11: ='INVENTARIO INICIAL'!G11 -> 0 | H11: ='INVENTARIO INICIAL'!H11 -> 0 | I11: =IF(H11=0,"",VLOOKUP(H11,Datos!$B$2:$D$908,2,FALSE)) | J11: =IF(H11=0,"",VLOOKUP(H11,Datos!$B$2:$D$908,3,FALSE)) | K11: ='INVENTARIO INICIAL'!K11 -> 0 | L11: ='INVENTARIO INICIAL'!L11 -> 0 | M11: ='INVENTARIO INICIAL'!M11 -> 0 | N11: ='INVENTARIO INICIAL'!N11 -> 0 | O11: ='INVENTARIO INICIAL'!O11 -> 0 | P11: ='INVENTARIO INICIAL'!P11 -> 0 | Q11: ='INVENTARIO INICIAL'!Q11 -> 0 | R11: ='INVENTARIO INICIAL'!R11 -> 0 | S11: ='INVENTARIO INICIAL'!S11 -> 0 | AF11: =IF(AI11>=AJ11,IF(AK11>=0,IF(AJ11>=0,AK11,"Error"))) -> 0 | AG11: ='INVENTARIO INICIAL'!T11 -> 0 | AH11: =AF11*AG11 -> 0 | AI11: =S11+T11 -> 0 | AJ11: =U11+V11+W11+X11+Y11+AB11 -> 0 | AK11: =AI11-AJ11 -> 0 | AL11: Marzo | AN11: ='INVENTARIO INICIAL'!X11 -> 0
A12: ='INVENTARIO INICIAL'!A12 -> Inventario | B12: ='INVENTARIO INICIAL'!B12 -> 0 | C12: =IF(B12=0,"",VLOOKUP(B12,Datos!$H$2:$K$39,2,FALSE)) | D12: =IF(B12=0,"",VLOOKUP(B12,Datos!$H$2:$K$39,3,FALSE)) | E12: =IF(B12=0,"",VLOOKUP(B12,Datos!$H$2:$K$39,4,FALSE)) | F12: ='INVENTARIO INICIAL'!F12 -> 0 | G12: ='INVENTARIO INICIAL'!G12 -> 0 | H12: ='INVENTARIO INICIAL'!H12 -> 0 | I12: =IF(H12=0,"",VLOOKUP(H12,Datos!$B$2:$D$908,2,FALSE)) | J12: =IF(H12=0,"",VLOOKUP(H12,Datos!$B$2:$D$908,3,FALSE)) | K12: ='INVENTARIO INICIAL'!K12 -> 0 | L12: ='INVENTARIO INICIAL'!L12 -> 0 | M12: ='INVENTARIO INICIAL'!M12 -> 0 | N12: ='INVENTARIO INICIAL'!N12 -> 0 | O12: ='INVENTARIO INICIAL'!O12 -> 0 | P12: ='INVENTARIO INICIAL'!P12 -> 0 | Q12: ='INVENTARIO INICIAL'!Q12 -> 0 | R12: ='INVENTARIO INICIAL'!R12 -> 0 | S12: ='INVENTARIO INICIAL'!S12 -> 0 | AF12: =IF(AI12>=AJ12,IF(AK12>=0,IF(AJ12>=0,AK12,"Error"))) -> 0 | AG12: ='INVENTARIO INICIAL'!T12 -> 0 | AH12: =AF12*AG12 -> 0 | AI12: =S12+T12 -> 0 | AJ12: =U12+V12+W12+X12+Y12+AB12 -> 0 | AK12: =AI12-AJ12 -> 0 | AL12: Marzo | AN12: ='INVENTARIO INICIAL'!X12 -> 0
A13: ='INVENTARIO INICIAL'!A13 -> Inventario | B13: ='INVENTARIO INICIAL'!B13 -> 0 | C13: =IF(B13=0,"",VLOOKUP(B13,Datos!$H$2:$K$39,2,FALSE)) | D13: =IF(B13=0,"",VLOOKUP(B13,Datos!$H$2:$K$39,3,FALSE)) | E13: =IF(B13=0,"",VLOOKUP(B13,Datos!$H$2:$K$39,4,FALSE)) | F13: ='INVENTARIO INICIAL'!F13 -> 0 | G13: ='INVENTARIO INICIAL'!G13 -> 0 | H13: ='INVENTARIO INICIAL'!H13 -> 0 | I13: =IF(H13=0,"",VLOOKUP(H13,Datos!$B$2:$D$908,2,FALSE)) | J13: =IF(H13=0,"",VLOOKUP(H13,Datos!$B$2:$D$908,3,FALSE)) | K13: ='INVENTARIO INICIAL'!K13 -> 0 | L13: ='INVENTARIO INICIAL'!L13 -> 0 | M13: ='INVENTARIO INICIAL'!M13 -> 0 | N13: ='INVENTARIO INICIAL'!N13 -> 0 | O13: ='INVENTARIO INICIAL'!O13 -> 0 | P13: ='INVENTARIO INICIAL'!P13 -> 0 | Q13: ='INVENTARIO INICIAL'!Q13 -> 0 | R13: ='INVENTARIO INICIAL'!R13 -> 0 | S13: ='INVENTARIO INICIAL'!S13 -> 0 | AF13: =IF(AI13>=AJ13,IF(AK13>=0,IF(AJ13>=0,AK13,"Error"))) -> 0 | AG13: ='INVENTARIO INICIAL'!T13 -> 0 | AH13: =AF13*AG13 -> 0 | AI13: =S13+T13 -> 0 | AJ13: =U13+V13+W13+X13+Y13+AB13 -> 0 | AK13: =AI13-AJ13 -> 0 | AL13: Marzo | AN13: ='INVENTARIO INICIAL'!X13 -> 0
A14: ='INVENTARIO INICIAL'!A14 -> Inventario | B14: ='INVENTARIO INICIAL'!B14 -> 0 | C14: =IF(B14=0,"",VLOOKUP(B14,Datos!$H$2:$K$39,2,FALSE)) | D14: =IF(B14=0,"",VLOOKUP(B14,Datos!$H$2:$K$39,3,FALSE)) | E14: =IF(B14=0,"",VLOOKUP(B14,Datos!$H$2:$K$39,4,FALSE)) | F14: ='INVENTARIO INICIAL'!F14 -> 0 | G14: ='INVENTARIO INICIAL'!G14 -> 0 | H14: ='INVENTARIO INICIAL'!H14 -> 0 | I14: =IF(H14=0,"",VLOOKUP(H14,Datos!$B$2:$D$908,2,FALSE)) | J14: =IF(H14=0,"",VLOOKUP(H14,Datos!$B$2:$D$908,3,FALSE)) | K14: ='INVENTARIO INICIAL'!K14 -> 0 | L14: ='INVENTARIO INICIAL'!L14 -> 0 | M14: ='INVENTARIO INICIAL'!M14 -> 0 | N14: ='INVENTARIO INICIAL'!N14 -> 0 | O14: ='INVENTARIO INICIAL'!O14 -> 0 | P14: ='INVENTARIO INICIAL'!P14 -> 0 | Q14: ='INVENTARIO INICIAL'!Q14 -> 0 | R14: ='INVENTARIO INICIAL'!R14 -> 0 | S14: ='INVENTARIO INICIAL'!S14 -> 0 | AF14: =IF(AI14>=AJ14,IF(AK14>=0,IF(AJ14>=0,AK14,"Error"))) -> 0 | AG14: ='INVENTARIO INICIAL'!T14 -> 0 | AH14: =AF14*AG14 -> 0 | AI14: =S14+T14 -> 0 | AJ14: =U14+V14+W14+X14+Y14+AB14 -> 0 | AK14: =AI14-AJ14 -> 0 | AL14: Marzo | AN14: ='INVENTARIO INICIAL'!X14 -> 0
A15: ='INVENTARIO INICIAL'!A15 -> Inventario | B15: ='INVENTARIO INICIAL'!B15 -> 0 | C15: =IF(B15=0,"",VLOOKUP(B15,Datos!$H$2:$K$39,2,FALSE)) | D15: =IF(B15=0,"",VLOOKUP(B15,Datos!$H$2:$K$39,3,FALSE)) | E15: =IF(B15=0,"",VLOOKUP(B15,Datos!$H$2:$K$39,4,FALSE)) | F15: ='INVENTARIO INICIAL'!F15 -> 0 | G15: ='INVENTARIO INICIAL'!G15 -> 0 | H15: ='INVENTARIO INICIAL'!H15 -> 0 | I15: =IF(H15=0,"",VLOOKUP(H15,Datos!$B$2:$D$908,2,FALSE)) | J15: =IF(H15=0,"",VLOOKUP(H15,Datos!$B$2:$D$908,3,FALSE)) | K15: ='INVENTARIO INICIAL'!K15 -> 0 | L15: ='INVENTARIO INICIAL'!L15 -> 0 | M15: ='INVENTARIO INICIAL'!M15 -> 0 | N15: ='INVENTARIO INICIAL'!N15 -> 0 | O15: ='INVENTARIO INICIAL'!O15 -> 0 | P15: ='INVENTARIO INICIAL'!P15 -> 0 | Q15: ='INVENTARIO INICIAL'!Q15 -> 0 | R15: ='INVENTARIO INICIAL'!R15 -> 0 | S15: ='INVENTARIO INICIAL'!S15 -> 0 | AF15: =IF(AI15>=AJ15,IF(AK15>=0,IF(AJ15>=0,AK15,"Error"))) -> 0 | AG15: ='INVENTARIO INICIAL'!T15 -> 0 | AH15: =AF15*AG15 -> 0 | AI15: =S15+T15 -> 0 | AJ15: =U15+V15+W15+X15+Y15+AB15 -> 0 | AK15: =AI15-AJ15 -> 0 | AL15: Marzo | AN15: ='INVENTARIO INICIAL'!X15 -> 0
A16: ='INVENTARIO INICIAL'!A16 -> Inventario | B16: ='INVENTARIO INICIAL'!B16 -> 0 | C16: =IF(B16=0,"",VLOOKUP(B16,Datos!$H$2:$K$39,2,FALSE)) | D16: =IF(B16=0,"",VLOOKUP(B16,Datos!$H$2:$K$39,3,FALSE)) | E16: =IF(B16=0,"",VLOOKUP(B16,Datos!$H$2:$K$39,4,FALSE)) | F16: ='INVENTARIO INICIAL'!F16 -> 0 | G16: ='INVENTARIO INICIAL'!G16 -> 0 | H16: ='INVENTARIO INICIAL'!H16 -> 0 | I16: =IF(H16=0,"",VLOOKUP(H16,Datos!$B$2:$D$908,2,FALSE)) | J16: =IF(H16=0,"",VLOOKUP(H16,Datos!$B$2:$D$908,3,FALSE)) | K16: ='INVENTARIO INICIAL'!K16 -> 0 | L16: ='INVENTARIO INICIAL'!L16 -> 0 | M16: ='INVENTARIO INICIAL'!M16 -> 0 | N16: ='INVENTARIO INICIAL'!N16 -> 0 | O16: ='INVENTARIO INICIAL'!O16 -> 0 | P16: ='INVENTARIO INICIAL'!P16 -> 0 | Q16: ='INVENTARIO INICIAL'!Q16 -> 0 | R16: ='INVENTARIO INICIAL'!R16 -> 0 | S16: ='INVENTARIO INICIAL'!S16 -> 0 | AF16: =IF(AI16>=AJ16,IF(AK16>=0,IF(AJ16>=0,AK16,"Error"))) -> 0 | AG16: ='INVENTARIO INICIAL'!T16 -> 0 | AH16: =AF16*AG16 -> 0 | AI16: =S16+T16 -> 0 | AJ16: =U16+V16+W16+X16+Y16+AB16 -> 0 | AK16: =AI16-AJ16 -> 0 | AL16: Marzo | AN16: ='INVENTARIO INICIAL'!X16 -> 0
A17: ='INVENTARIO INICIAL'!A17 -> Inventario | B17: ='INVENTARIO INICIAL'!B17 -> 0 | C17: =IF(B17=0,"",VLOOKUP(B17,Datos!$H$2:$K$39,2,FALSE)) | D17: =IF(B17=0,"",VLOOKUP(B17,Datos!$H$2:$K$39,3,FALSE)) | E17: =IF(B17=0,"",VLOOKUP(B17,Datos!$H$2:$K$39,4,FALSE)) | F17: ='INVENTARIO INICIAL'!F17 -> 0 | G17: ='INVENTARIO INICIAL'!G17 -> 0 | H17: ='INVENTARIO INICIAL'!H17 -> 0 | I17: =IF(H17=0,"",VLOOKUP(H17,Datos!$B$2:$D$908,2,FALSE)) | J17: =IF(H17=0,"",VLOOKUP(H17,Datos!$B$2:$D$908,3,FALSE)) | K17: ='INVENTARIO INICIAL'!K17 -> 0 | L17: ='INVENTARIO INICIAL'!L17 -> 0 | M17: ='INVENTARIO INICIAL'!M17 -> 0 | N17: ='INVENTARIO INICIAL'!N17 -> 0 | O17: ='INVENTARIO INICIAL'!O17 -> 0 | P17: ='INVENTARIO INICIAL'!P17 -> 0 | Q17: ='INVENTARIO INICIAL'!Q17 -> 0 | R17: ='INVENTARIO INICIAL'!R17 -> 0 | S17: ='INVENTARIO INICIAL'!S17 -> 0 | AF17: =IF(AI17>=AJ17,IF(AK17>=0,IF(AJ17>=0,AK17,"Error"))) -> 0 | AG17: ='INVENTARIO INICIAL'!T17 -> 0 | AH17: =AF17*AG17 -> 0 | AI17: =S17+T17 -> 0 | AJ17: =U17+V17+W17+X17+Y17+AB17 -> 0 | AK17: =AI17-AJ17 -> 0 | AL17: Marzo | AN17: ='INVENTARIO INICIAL'!X17 -> 0
A18: ='INVENTARIO INICIAL'!A18 -> Inventario | B18: ='INVENTARIO INICIAL'!B18 -> 0 | C18: =IF(B18=0,"",VLOOKUP(B18,Datos!$H$2:$K$39,2,FALSE)) | D18: =IF(B18=0,"",VLOOKUP(B18,Datos!$H$2:$K$39,3,FALSE)) | E18: =IF(B18=0,"",VLOOKUP(B18,Datos!$H$2:$K$39,4,FALSE)) | F18: ='INVENTARIO INICIAL'!F18 -> 0 | G18: ='INVENTARIO INICIAL'!G18 -> 0 | H18: ='INVENTARIO INICIAL'!H18 -> 0 | I18: =IF(H18=0,"",VLOOKUP(H18,Datos!$B$2:$D$908,2,FALSE)) | J18: =IF(H18=0,"",VLOOKUP(H18,Datos!$B$2:$D$908,3,FALSE)) | K18: ='INVENTARIO INICIAL'!K18 -> 0 | L18: ='INVENTARIO INICIAL'!L18 -> 0 | M18: ='INVENTARIO INICIAL'!M18 -> 0 | N18: ='INVENTARIO INICIAL'!N18 -> 0 | O18: ='INVENTARIO INICIAL'!O18 -> 0 | P18: ='INVENTARIO INICIAL'!P18 -> 0 | Q18: ='INVENTARIO INICIAL'!Q18 -> 0 | R18: ='INVENTARIO INICIAL'!R18 -> 0 | S18: ='INVENTARIO INICIAL'!S18 -> 0 | AF18: =IF(AI18>=AJ18,IF(AK18>=0,IF(AJ18>=0,AK18,"Error"))) -> 0 | AG18: ='INVENTARIO INICIAL'!T18 -> 0 | AH18: =AF18*AG18 -> 0 | AI18: =S18+T18 -> 0 | AJ18: =U18+V18+W18+X18+Y18+AB18 -> 0 | AK18: =AI18-AJ18 -> 0 | AL18: Marzo | AN18: ='INVENTARIO INICIAL'!X18 -> 0
... A360: ='INVENTARIO INICIAL'!A360 -> Inventario | B360: ='INVENTARIO INICIAL'!B360 -> 0 | C360: =IF(B360=0,"",VLOOKUP(B360,Datos!$H$2:$K$39,2,FALSE)) | D360: =IF(B360=0,"",VLOOKUP(B360,Datos!$H$2:$K$39,3,FALSE)) | E360: =IF(B360=0,"",VLOOKUP(B360,Datos!$H$2:$K$39,4,FALSE)) | F360: ='INVENTARIO INICIAL'!F360 -> 0 | G360: ='INVENTARIO INICIAL'!G360 -> 0 | H360: ='INVENTARIO INICIAL'!H360 -> 0 | I360: =IF(H360=0,"",VLOOKUP(H360,Datos!$B$2:$D$908,2,FALSE)) | J360: =IF(H360=0,"",VLOOKUP(H360,Datos!$B$2:$D$908,3,FALSE)) | K360: ='INVENTARIO INICIAL'!K360 -> 0 | L360: ='INVENTARIO INICIAL'!L360 -> 0 | M360: ='INVENTARIO INICIAL'!M360 -> 0 | N360: ='INVENTARIO INICIAL'!N360 -> 0 | O360: ='INVENTARIO INICIAL'!O360 -> 0 | P360: ='INVENTARIO INICIAL'!P360 -> 0 | Q360: ='INVENTARIO INICIAL'!Q360 -> 0 | R360: ='INVENTARIO INICIAL'!R360 -> 0 | S360: ='INVENTARIO INICIAL'!S360 -> 0 | AF360: =IF(AI360>=AJ360,IF(AK360>=0,IF(AJ360>=0,AK360,"Error"))) -> 0 | AG360: ='INVENTARIO INICIAL'!T360 -> 0 | AH360: =AF360*AG360 -> 0 | AI360: =S360+T360 -> 0 | AJ360: =U360+V360+W360+X360+Y360+AB360 -> 0 | AK360: =AI360-AJ360 -> 0 | AL360: Marzo | AN360: ='INVENTARIO INICIAL'!X360 -> 0
A361: Ingresos | C361: =IF(B361=0,"",VLOOKUP(B361,Datos!$H$2:$K$39,2,FALSE)) | D361: =IF(B361=0,"",VLOOKUP(B361,Datos!$H$2:$K$39,3,FALSE)) | E361: =IF(B361=0,"",VLOOKUP(B361,Datos!$H$2:$K$39,4,FALSE)) | I361: =IF(H361=0,"",VLOOKUP(H361,Datos!$B$2:$D$908,2,FALSE)) | J361: =IF(H361=0,"",VLOOKUP(H361,Datos!$B$2:$D$908,3,FALSE)) | AF361: =IF(AI361>=AJ361,IF(AK361>=0,IF(AJ361>=0,AK361,"Error"))) -> 0 | AG361: 0 | AH361: =AF361*AG361 -> 0 | AI361: =S361+T361 -> 0 | AJ361: =U361+V361+W361+X361+Y361+AB361 -> 0 | AK361: =AI361-AJ361 -> 0 | AL361: Marzo
A362: Ingresos | C362: =IF(B362=0,"",VLOOKUP(B362,Datos!$H$2:$K$39,2,FALSE)) | D362: =IF(B362=0,"",VLOOKUP(B362,Datos!$H$2:$K$39,3,FALSE)) | E362: =IF(B362=0,"",VLOOKUP(B362,Datos!$H$2:$K$39,4,FALSE)) | I362: =IF(H362=0,"",VLOOKUP(H362,Datos!$B$2:$D$908,2,FALSE)) | J362: =IF(H362=0,"",VLOOKUP(H362,Datos!$B$2:$D$908,3,FALSE)) | AF362: =IF(AI362>=AJ362,IF(AK362>=0,IF(AJ362>=0,AK362,"Error"))) -> 0 | AG362: 0 | AH362: =AF362*AG362 -> 0 | AI362: =S362+T362 -> 0 | AJ362: =U362+V362+W362+X362+Y362+AB362 -> 0 | AK362: =AI362-AJ362 -> 0 | AL362: Marzo
A363: Ingresos | C363: =IF(B363=0,"",VLOOKUP(B363,Datos!$H$2:$K$39,2,FALSE)) | D363: =IF(B363=0,"",VLOOKUP(B363,Datos!$H$2:$K$39,3,FALSE)) | E363: =IF(B363=0,"",VLOOKUP(B363,Datos!$H$2:$K$39,4,FALSE)) | I363: =IF(H363=0,"",VLOOKUP(H363,Datos!$B$2:$D$908,2,FALSE)) | J363: =IF(H363=0,"",VLOOKUP(H363,Datos!$B$2:$D$908,3,FALSE)) | AF363: =IF(AI363>=AJ363,IF(AK363>=0,IF(AJ363>=0,AK363,"Error"))) -> 0 | AG363: 0 | AH363: =AF363*AG363 -> 0 | AI363: =S363+T363 -> 0 | AJ363: =U363+V363+W363+X363+Y363+AB363 -> 0 | AK363: =AI363-AJ363 -> 0 | AL363: Marzo
A364: Ingresos | C364: =IF(B364=0,"",VLOOKUP(B364,Datos!$H$2:$K$39,2,FALSE)) | D364: =IF(B364=0,"",VLOOKUP(B364,Datos!$H$2:$K$39,3,FALSE)) | E364: =IF(B364=0,"",VLOOKUP(B364,Datos!$H$2:$K$39,4,FALSE)) | I364: =IF(H364=0,"",VLOOKUP(H364,Datos!$B$2:$D$908,2,FALSE)) | J364: =IF(H364=0,"",VLOOKUP(H364,Datos!$B$2:$D$908,3,FALSE)) | AF364: =IF(AI364>=AJ364,IF(AK364>=0,IF(AJ364>=0,AK364,"Error"))) -> 0 | AG364: 0 | AH364: =AF364*AG364 -> 0 | AI364: =S364+T364 -> 0 | AJ364: =U364+V364+W364+X364+Y364+AB364 -> 0 | AK364: =AI364-AJ364 -> 0 | AL364: Marzo
A365: Ingresos | C365: =IF(B365=0,"",VLOOKUP(B365,Datos!$H$2:$K$39,2,FALSE)) | D365: =IF(B365=0,"",VLOOKUP(B365,Datos!$H$2:$K$39,3,FALSE)) | E365: =IF(B365=0,"",VLOOKUP(B365,Datos!$H$2:$K$39,4,FALSE)) | I365: =IF(H365=0,"",VLOOKUP(H365,Datos!$B$2:$D$908,2,FALSE)) | J365: =IF(H365=0,"",VLOOKUP(H365,Datos!$B$2:$D$908,3,FALSE)) | AF365: =IF(AI365>=AJ365,IF(AK365>=0,IF(AJ365>=0,AK365,"Error"))) -> 0 | AG365: 0 | AH365: =AF365*AG365 -> 0 | AI365: =S365+T365 -> 0 | AJ365: =U365+V365+W365+X365+Y365+AB365 -> 0 | AK365: =AI365-AJ365 -> 0 | AL365: Marzo
A366: Ingresos | C366: =IF(B366=0,"",VLOOKUP(B366,Datos!$H$2:$K$39,2,FALSE)) | D366: =IF(B366=0,"",VLOOKUP(B366,Datos!$H$2:$K$39,3,FALSE)) | E366: =IF(B366=0,"",VLOOKUP(B366,Datos!$H$2:$K$39,4,FALSE)) | I366: =IF(H366=0,"",VLOOKUP(H366,Datos!$B$2:$D$908,2,FALSE)) | J366: =IF(H366=0,"",VLOOKUP(H366,Datos!$B$2:$D$908,3,FALSE)) | AF366: =IF(AI366>=AJ366,IF(AK366>=0,IF(AJ366>=0,AK366,"Error"))) -> 0 | AG366: 0 | AH366: =AF366*AG366 -> 0 | AI366: =S366+T366 -> 0 | AJ366: =U366+V366+W366+X366+Y366+AB366 -> 0 | AK366: =AI366-AJ366 -> 0 | AL366: Marzo
A367: Ingresos | C367: =IF(B367=0,"",VLOOKUP(B367,Datos!$H$2:$K$39,2,FALSE)) | D367: =IF(B367=0,"",VLOOKUP(B367,Datos!$H$2:$K$39,3,FALSE)) | E367: =IF(B367=0,"",VLOOKUP(B367,Datos!$H$2:$K$39,4,FALSE)) | I367: =IF(H367=0,"",VLOOKUP(H367,Datos!$B$2:$D$908,2,FALSE)) | J367: =IF(H367=0,"",VLOOKUP(H367,Datos!$B$2:$D$908,3,FALSE)) | AF367: =IF(AI367>=AJ367,IF(AK367>=0,IF(AJ367>=0,AK367,"Error"))) -> 0 | AG367: 0 | AH367: =AF367*AG367 -> 0 | AI367: =S367+T367 -> 0 | AJ367: =U367+V367+W367+X367+Y367+AB367 -> 0 | AK367: =AI367-AJ367 -> 0 | AL367: Marzo
A368: Ingresos | C368: =IF(B368=0,"",VLOOKUP(B368,Datos!$H$2:$K$39,2,FALSE)) | D368: =IF(B368=0,"",VLOOKUP(B368,Datos!$H$2:$K$39,3,FALSE)) | E368: =IF(B368=0,"",VLOOKUP(B368,Datos!$H$2:$K$39,4,FALSE)) | I368: =IF(H368=0,"",VLOOKUP(H368,Datos!$B$2:$D$908,2,FALSE)) | J368: =IF(H368=0,"",VLOOKUP(H368,Datos!$B$2:$D$908,3,FALSE)) | AF368: =IF(AI368>=AJ368,IF(AK368>=0,IF(AJ368>=0,AK368,"Error"))) -> 0 | AG368: 0 | AH368: =AF368*AG368 -> 0 | AI368: =S368+T368 -> 0 | AJ368: =U368+V368+W368+X368+Y368+AB368 -> 0 | AK368: =AI368-AJ368 -> 0 | AL368: Marzo
A369: Ingresos | C369: =IF(B369=0,"",VLOOKUP(B369,Datos!$H$2:$K$39,2,FALSE)) | D369: =IF(B369=0,"",VLOOKUP(B369,Datos!$H$2:$K$39,3,FALSE)) | E369: =IF(B369=0,"",VLOOKUP(B369,Datos!$H$2:$K$39,4,FALSE)) | I369: =IF(H369=0,"",VLOOKUP(H369,Datos!$B$2:$D$908,2,FALSE)) | J369: =IF(H369=0,"",VLOOKUP(H369,Datos!$B$2:$D$908,3,FALSE)) | AF369: =IF(AI369>=AJ369,IF(AK369>=0,IF(AJ369>=0,AK369,"Error"))) -> 0 | AG369: 0 | AH369: =AF369*AG369 -> 0 | AI369: =S369+T369 -> 0 | AJ369: =U369+V369+W369+X369+Y369+AB369 -> 0 | AK369: =AI369-AJ369 -> 0 | AL369: Marzo
A370: Ingresos | C370: =IF(B370=0,"",VLOOKUP(B370,Datos!$H$2:$K$39,2,FALSE)) | D370: =IF(B370=0,"",VLOOKUP(B370,Datos!$H$2:$K$39,3,FALSE)) | E370: =IF(B370=0,"",VLOOKUP(B370,Datos!$H$2:$K$39,4,FALSE)) | I370: =IF(H370=0,"",VLOOKUP(H370,Datos!$B$2:$D$908,2,FALSE)) | J370: =IF(H370=0,"",VLOOKUP(H370,Datos!$B$2:$D$908,3,FALSE)) | AF370: =IF(AI370>=AJ370,IF(AK370>=0,IF(AJ370>=0,AK370,"Error"))) -> 0 | AG370: 0 | AH370: =AF370*AG370 -> 0 | AI370: =S370+T370 -> 0 | AJ370: =U370+V370+W370+X370+Y370+AB370 -> 0 | AK370: =AI370-AJ370 -> 0 | AL370: Marzo
A371: Ingresos | C371: =IF(B371=0,"",VLOOKUP(B371,Datos!$H$2:$K$39,2,FALSE)) | D371: =IF(B371=0,"",VLOOKUP(B371,Datos!$H$2:$K$39,3,FALSE)) | E371: =IF(B371=0,"",VLOOKUP(B371,Datos!$H$2:$K$39,4,FALSE)) | I371: =IF(H371=0,"",VLOOKUP(H371,Datos!$B$2:$D$908,2,FALSE)) | J371: =IF(H371=0,"",VLOOKUP(H371,Datos!$B$2:$D$908,3,FALSE)) | AF371: =IF(AI371>=AJ371,IF(AK371>=0,IF(AJ371>=0,AK371,"Error"))) -> 0 | AG371: 0 | AH371: =AF371*AG371 -> 0 | AI371: =S371+T371 -> 0 | AJ371: =U371+V371+W371+X371+Y371+AB371 -> 0 | AK371: =AI371-AJ371 -> 0 | AL371: Marzo
A372: Ingresos | C372: =IF(B372=0,"",VLOOKUP(B372,Datos!$H$2:$K$39,2,FALSE)) | D372: =IF(B372=0,"",VLOOKUP(B372,Datos!$H$2:$K$39,3,FALSE)) | E372: =IF(B372=0,"",VLOOKUP(B372,Datos!$H$2:$K$39,4,FALSE)) | I372: =IF(H372=0,"",VLOOKUP(H372,Datos!$B$2:$D$908,2,FALSE)) | J372: =IF(H372=0,"",VLOOKUP(H372,Datos!$B$2:$D$908,3,FALSE)) | AF372: =IF(AI372>=AJ372,IF(AK372>=0,IF(AJ372>=0,AK372,"Error"))) -> 0 | AG372: 0 | AH372: =AF372*AG372 -> 0 | AI372: =S372+T372 -> 0 | AJ372: =U372+V372+W372+X372+Y372+AB372 -> 0 | AK372: =AI372-AJ372 -> 0 | AL372: Marzo
... A490: Ingresos | C490: =IF(B490=0,"",VLOOKUP(B490,Datos!$H$2:$K$39,2,FALSE)) | D490: =IF(B490=0,"",VLOOKUP(B490,Datos!$H$2:$K$39,3,FALSE)) | E490: =IF(B490=0,"",VLOOKUP(B490,Datos!$H$2:$K$39,4,FALSE)) | I490: =IF(H490=0,"",VLOOKUP(H490,Datos!$B$2:$D$908,2,FALSE)) | J490: =IF(H490=0,"",VLOOKUP(H490,Datos!$B$2:$D$908,3,FALSE)) | AF490: =IF(AI490>=AJ490,IF(AK490>=0,IF(AJ490>=0,AK490,"Error"))) -> 0 | AG490: 0 | AH490: =AF490*AG490 -> 0 | AI490: =S490+T490 -> 0 | AJ490: =U490+V490+W490+X490+Y490+AB490 -> 0 | AK490: =AI490-AJ490 -> 0 | AL490: Marzo
A491: Total Marzo | R491: Total | S491: =SUM(S7:S490) -> 0 | T491: =SUM(T7:T490) -> 0 | U491: =SUM(U7:U490) -> 0 | V491: =SUM(V7:V490) -> 0 | W491: =SUM(W7:W490) -> 0 | X491: =SUM(X7:X490) -> 0 | Y491: =SUM(Y7:Y490) -> 0 | AB491: =SUM(AB7:AB490) -> 0 | AF491: =SUM(AF7:AF490) -> 0 | AH491: =SUM(AH7:AH490) -> 0

Sheet Reporte Junio 2026
B1: Control Inventario de Plantas SIGI GBCC 8 | 2026
B2: Viveros, centros de acopio y acondicionamiento CONAF
B3: Reporte Junio 2026
T4: INGRESOS Y EGRESOS DE PLANTAS EN EL SEGUNDO TRIMESTRE (ABRIL A JUNIO)
A5: ANTECEDENTES DEL VIVERO | H5: ANTECEDENTES DE LA ESPECIE | T5: N° DE PLANTAS NUEVAS | U5: N° DE PLANTAS ENTREGADAS Y/O VENDIDAS | X5: Movimientos Internos (Cambios Rango de Altura o Contenedor) | Y5: TRASLADOS INTERNOS A OTRAS UNIDADES CONAF | AB5: BAJA DE PLANTAS DE INVENTARIO | AF5: STOCK | AG5: VALORIZACIÓN
A6: Ítems | B6: Unidad Productiva | C6: Unidad Administrativa | D6: Provincia | E6: Comuna | F6: Encargado | G6: Teléfono de Contacto | H6: Nombre Científico | I6: Nombre Común | J6: Origen | K6: Fuente de Abastecimiento | L6: Destino de la Planta | M6: Tipo de Reproducción | N6: Tipo de Contenedor | O6: Fecha Ingreso a Inventario (Día/Mes/Año) | P6: Tiempo de Viverización (años) | Q6: Rango de Altura | R6: Sectores del Vivero | S6: N° Total Plantas Control Inventario Marzo 2026 | T6: N° Plantas NUEVAS Ingresadas a Inventario | U6: N° Entregas por Difusión | V6: N° Entregas a Programas | W6: N° Plantas Venta | X6: N° Plantas (M.I.) | Y6: N° Plantas Trasladadas | Z6: Unidades Recepción de Traslado | AA6: N° de Documento, Factura o Guía de Despacho | AB6: N° Plantas de Baja | AC6: Causas | AD6: N° Resolución | AE6: Fecha de Resolución | AF6: N° TOTAL DE PLANTAS EN INVENTARIO JUNIO 2026 | AG6: Valor Neto ($) por planta | AH6: Valor Total ($) por lote | AI6: Ingresos | AJ6: Egresos | AK6: stock Junio | AL6: MES REPORTE | AN6: Código de planta para Guía de Despacho
A7: ='Reporte Marzo 2026'!A7 -> Inventario | B7: ='INVENTARIO INICIAL'!B7 -> 0 | C7: =IF(B7=0,"",VLOOKUP(B7,Datos!$H$2:$K$39,2,FALSE)) | D7: =IF(B7=0,"",VLOOKUP(B7,Datos!$H$2:$K$39,3,FALSE)) | E7: =IF(B7=0,"",VLOOKUP(B7,Datos!$H$2:$K$39,4,FALSE)) | F7: ='INVENTARIO INICIAL'!F7 -> 0 | G7: ='INVENTARIO INICIAL'!G7 -> 0 | H7: ='INVENTARIO INICIAL'!H7 -> 0 | I7: =IF(H7=0,"",VLOOKUP(H7,Datos!$B$2:$D$908,2,FALSE)) | J7: =IF(H7=0,"",VLOOKUP(H7,Datos!$B$2:$D$908,3,FALSE)) | K7: ='INVENTARIO INICIAL'!K7 -> 0 | L7: ='INVENTARIO INICIAL'!L7 -> 0 | M7: ='INVENTARIO INICIAL'!M7 -> 0 | N7: ='INVENTARIO INICIAL'!N7 -> 0 | O7: ='INVENTARIO INICIAL'!O7 -> 0 | P7: ='INVENTARIO INICIAL'!P7 -> 0 | Q7: ='INVENTARIO INICIAL'!Q7 -> 0 | R7: ='INVENTARIO INICIAL'!R7 -> 0 | S7: ='Reporte Marzo 2026'!AF7 -> 0 | AF7: =IF(AI7>=AJ7,IF(AK7>=0,IF(AJ7>=0,AK7,"Error"))) -> 0 | AG7: ='Reporte Marzo 2026'!AG7 -> 0 | AH7: =AF7*AG7 -> 0 | AI7: =S7+T7 -> 0 | AJ7: =U7+V7+W7+X7+Y7+AB7 -> 0 | AK7: =AI7-AJ7 -> 0 | AL7: Junio | AN7: ='INVENTARIO INICIAL'!X7 -> 0
A8: ='Reporte Marzo 2026'!A8 -> Inventario | B8: ='INVENTARIO INICIAL'!B8 -> 0 | C8: =IF(B8=0,"",VLOOKUP(B8,Datos!$H$2:$K$39,2,FALSE)) | D8: =IF(B8=0,"",VLOOKUP(B8,Datos!$H$2:$K$39,3,FALSE)) | E8: =IF(B8=0,"",VLOOKUP(B8,Datos!$H$2:$K$39,4,FALSE)) | F8: ='INVENTARIO INICIAL'!F8 -> 0 | G8: ='INVENTARIO INICIAL'!G8 -> 0 | H8: ='INVENTARIO INICIAL'!H8 -> 0 | I8: =IF(H8=0,"",VLOOKUP(H8,Datos!$B$2:$D$908,2,FALSE)) | J8: =IF(H8=0,"",VLOOKUP(H8,Datos!$B$2:$D$908,3,FALSE)) | K8: ='INVENTARIO INICIAL'!K8 -> 0 | L8: ='INVENTARIO INICIAL'!L8 -> 0 | M8: ='INVENTARIO INICIAL'!M8 -> 0 | N8: ='INVENTARIO INICIAL'!N8 -> 0 | O8: ='INVENTARIO INICIAL'!O8 -> 0 | P8: ='INVENTARIO INICIAL'!P8 -> 0 | Q8: ='INVENTARIO INICIAL'!Q8 -> 0 | R8: ='INVENTARIO INICIAL'!R8 -> 0 | S8: ='Reporte Marzo 2026'!AF8 -> 0 | AF8: =IF(AI8>=AJ8,IF(AK8>=0,IF(AJ8>=0,AK8,"Error"))) -> 0 | AG8: ='Reporte Marzo 2026'!AG8 -> 0 | AH8: =AF8*AG8 -> 0 | AI8: =S8+T8 -> 0 | AJ8: =U8+V8+W8+X8+Y8+AB8 -> 0 | AK8: =AI8-AJ8 -> 0 | AL8: Junio | AN8: ='INVENTARIO INICIAL'!X8 -> 0
A9: ='Reporte Marzo 2026'!A9 -> Inventario | B9: ='INVENTARIO INICIAL'!B9 -> 0 | C9: =IF(B9=0,"",VLOOKUP(B9,Datos!$H$2:$K$39,2,FALSE)) | D9: =IF(B9=0,"",VLOOKUP(B9,Datos!$H$2:$K$39,3,FALSE)) | E9: =IF(B9=0,"",VLOOKUP(B9,Datos!$H$2:$K$39,4,FALSE)) | F9: ='INVENTARIO INICIAL'!F9 -> 0 | G9: ='INVENTARIO INICIAL'!G9 -> 0 | H9: ='INVENTARIO INICIAL'!H9 -> 0 | I9: =IF(H9=0,"",VLOOKUP(H9,Datos!$B$2:$D$908,2,FALSE)) | J9: =IF(H9=0,"",VLOOKUP(H9,Datos!$B$2:$D$908,3,FALSE)) | K9: ='INVENTARIO INICIAL'!K9 -> 0 | L9: ='INVENTARIO INICIAL'!L9 -> 0 | M9: ='INVENTARIO INICIAL'!M9 -> 0 | N9: ='INVENTARIO INICIAL'!N9 -> 0 | O9: ='INVENTARIO INICIAL'!O9 -> 0 | P9: ='INVENTARIO INICIAL'!P9 -> 0 | Q9: ='INVENTARIO INICIAL'!Q9 -> 0 | R9: ='INVENTARIO INICIAL'!R9 -> 0 | S9: ='Reporte Marzo 2026'!AF9 -> 0 | AF9: =IF(AI9>=AJ9,IF(AK9>=0,IF(AJ9>=0,AK9,"Error"))) -> 0 | AG9: ='Reporte Marzo 2026'!AG9 -> 0 | AH9: =AF9*AG9 -> 0 | AI9: =S9+T9 -> 0 | AJ9: =U9+V9+W9+X9+Y9+AB9 -> 0 | AK9: =AI9-AJ9 -> 0 | AL9: Junio | AN9: ='INVENTARIO INICIAL'!X9 -> 0
A10: ='Reporte Marzo 2026'!A10 -> Inventario | B10: ='INVENTARIO INICIAL'!B10 -> 0 | C10: =IF(B10=0,"",VLOOKUP(B10,Datos!$H$2:$K$39,2,FALSE)) | D10: =IF(B10=0,"",VLOOKUP(B10,Datos!$H$2:$K$39,3,FALSE)) | E10: =IF(B10=0,"",VLOOKUP(B10,Datos!$H$2:$K$39,4,FALSE)) | F10: ='INVENTARIO INICIAL'!F10 -> 0 | G10: ='INVENTARIO INICIAL'!G10 -> 0 | H10: ='INVENTARIO INICIAL'!H10 -> 0 | I10: =IF(H10=0,"",VLOOKUP(H10,Datos!$B$2:$D$908,2,FALSE)) | J10: =IF(H10=0,"",VLOOKUP(H10,Datos!$B$2:$D$908,3,FALSE)) | K10: ='INVENTARIO INICIAL'!K10 -> 0 | L10: ='INVENTARIO INICIAL'!L10 -> 0 | M10: ='INVENTARIO INICIAL'!M10 -> 0 | N10: ='INVENTARIO INICIAL'!N10 -> 0 | O10: ='INVENTARIO INICIAL'!O10 -> 0 | P10: ='INVENTARIO INICIAL'!P10 -> 0 | Q10: ='INVENTARIO INICIAL'!Q10 -> 0 | R10: ='INVENTARIO INICIAL'!R10 -> 0 | S10: ='Reporte Marzo 2026'!AF10 -> 0 | AF10: =IF(AI10>=AJ10,IF(AK10>=0,IF(AJ10>=0,AK10,"Error"))) -> 0 | AG10: ='Reporte Marzo 2026'!AG10 -> 0 | AH10: =AF10*AG10 -> 0 | AI10: =S10+T10 -> 0 | AJ10: =U10+V10+W10+X10+Y10+AB10 -> 0 | AK10: =AI10-AJ10 -> 0 | AL10: Junio | AN10: ='INVENTARIO INICIAL'!X10 -> 0
A11: ='Reporte Marzo 2026'!A11 -> Inventario | B11: ='INVENTARIO INICIAL'!B11 -> 0 | C11: =IF(B11=0,"",VLOOKUP(B11,Datos!$H$2:$K$39,2,FALSE)) | D11: =IF(B11=0,"",VLOOKUP(B11,Datos!$H$2:$K$39,3,FALSE)) | E11: =IF(B11=0,"",VLOOKUP(B11,Datos!$H$2:$K$39,4,FALSE)) | F11: ='INVENTARIO INICIAL'!F11 -> 0 | G11: ='INVENTARIO INICIAL'!G11 -> 0 | H11: ='INVENTARIO INICIAL'!H11 -> 0 | I11: =IF(H11=0,"",VLOOKUP(H11,Datos!$B$2:$D$908,2,FALSE)) | J11: =IF(H11=0,"",VLOOKUP(H11,Datos!$B$2:$D$908,3,FALSE)) | K11: ='INVENTARIO INICIAL'!K11 -> 0 | L11: ='INVENTARIO INICIAL'!L11 -> 0 | M11: ='INVENTARIO INICIAL'!M11 -> 0 | N11: ='INVENTARIO INICIAL'!N11 -> 0 | O11: ='INVENTARIO INICIAL'!O11 -> 0 | P11: ='INVENTARIO INICIAL'!P11 -> 0 | Q11: ='INVENTARIO INICIAL'!Q11 -> 0 | R11: ='INVENTARIO INICIAL'!R11 -> 0 | S11: ='Reporte Marzo 2026'!AF11 -> 0 | AF11: =IF(AI11>=AJ11,IF(AK11>=0,IF(AJ11>=0,AK11,"Error"))) -> 0 | AG11: ='Reporte Marzo 2026'!AG11 -> 0 | AH11: =AF11*AG11 -> 0 | AI11: =S11+T11 -> 0 | AJ11: =U11+V11+W11+X11+Y11+AB11 -> 0 | AK11: =AI11-AJ11 -> 0 | AL11: Junio | AN11: ='INVENTARIO INICIAL'!X11 -> 0
A12: ='Reporte Marzo 2026'!A12 -> Inventario | B12: ='INVENTARIO INICIAL'!B12 -> 0 | C12: =IF(B12=0,"",VLOOKUP(B12,Datos!$H$2:$K$39,2,FALSE)) | D12: =IF(B12=0,"",VLOOKUP(B12,Datos!$H$2:$K$39,3,FALSE)) | E12: =IF(B12=0,"",VLOOKUP(B12,Datos!$H$2:$K$39,4,FALSE)) | F12: ='INVENTARIO INICIAL'!F12 -> 0 | G12: ='INVENTARIO INICIAL'!G12 -> 0 | H12: ='INVENTARIO INICIAL'!H12 -> 0 | I12: =IF(H12=0,"",VLOOKUP(H12,Datos!$B$2:$D$908,2,FALSE)) | J12: =IF(H12=0,"",VLOOKUP(H12,Datos!$B$2:$D$908,3,FALSE)) | K12: ='INVENTARIO INICIAL'!K12 -> 0 | L12: ='INVENTARIO INICIAL'!L12 -> 0 | M12: ='INVENTARIO INICIAL'!M12 -> 0 | N12: ='INVENTARIO INICIAL'!N12 -> 0 | O12: ='INVENTARIO INICIAL'!O12 -> 0 | P12: ='INVENTARIO INICIAL'!P12 -> 0 | Q12: ='INVENTARIO INICIAL'!Q12 -> 0 | R12: ='INVENTARIO INICIAL'!R12 -> 0 | S12: ='Reporte Marzo 2026'!AF12 -> 0 | AF12: =IF(AI12>=AJ12,IF(AK12>=0,IF(AJ12>=0,AK12,"Error"))) -> 0 | AG12: ='Reporte Marzo 2026'!AG12 -> 0 | AH12: =AF12*AG12 -> 0 | AI12: =S12+T12 -> 0 | AJ12: =U12+V12+W12+X12+Y12+AB12 -> 0 | AK12: =AI12-AJ12 -> 0 | AL12: Junio | AN12: ='INVENTARIO INICIAL'!X12 -> 0
A13: ='Reporte Marzo 2026'!A13 -> Inventario | B13: ='INVENTARIO INICIAL'!B13 -> 0 | C13: =IF(B13=0,"",VLOOKUP(B13,Datos!$H$2:$K$39,2,FALSE)) | D13: =IF(B13=0,"",VLOOKUP(B13,Datos!$H$2:$K$39,3,FALSE)) | E13: =IF(B13=0,"",VLOOKUP(B13,Datos!$H$2:$K$39,4,FALSE)) | F13: ='INVENTARIO INICIAL'!F13 -> 0 | G13: ='INVENTARIO INICIAL'!G13 -> 0 | H13: ='INVENTARIO INICIAL'!H13 -> 0 | I13: =IF(H13=0,"",VLOOKUP(H13,Datos!$B$2:$D$908,2,FALSE)) | J13: =IF(H13=0,"",VLOOKUP(H13,Datos!$B$2:$D$908,3,FALSE)) | K13: ='INVENTARIO INICIAL'!K13 -> 0 | L13: ='INVENTARIO INICIAL'!L13 -> 0 | M13: ='INVENTARIO INICIAL'!M13 -> 0 | N13: ='INVENTARIO INICIAL'!N13 -> 0 | O13: ='INVENTARIO INICIAL'!O13 -> 0 | P13: ='INVENTARIO INICIAL'!P13 -> 0 | Q13: ='INVENTARIO INICIAL'!Q13 -> 0 | R13: ='INVENTARIO INICIAL'!R13 -> 0 | S13: ='Reporte Marzo 2026'!AF13 -> 0 | AF13: =IF(AI13>=AJ13,IF(AK13>=0,IF(AJ13>=0,AK13,"Error"))) -> 0 | AG13: ='Reporte Marzo 2026'!AG13 -> 0 | AH13: =AF13*AG13 -> 0 | AI13: =S13+T13 -> 0 | AJ13: =U13+V13+W13+X13+Y13+AB13 -> 0 | AK13: =AI13-AJ13 -> 0 | AL13: Junio | AN13: ='INVENTARIO INICIAL'!X13 -> 0
A14: ='Reporte Marzo 2026'!A14 -> Inventario | B14: ='INVENTARIO INICIAL'!B14 -> 0 | C14: =IF(B14=0,"",VLOOKUP(B14,Datos!$H$2:$K$39,2,FALSE)) | D14: =IF(B14=0,"",VLOOKUP(B14,Datos!$H$2:$K$39,3,FALSE)) | E14: =IF(B14=0,"",VLOOKUP(B14,Datos!$H$2:$K$39,4,FALSE)) | F14: ='INVENTARIO INICIAL'!F14 -> 0 | G14: ='INVENTARIO INICIAL'!G14 -> 0 | H14: ='INVENTARIO INICIAL'!H14 -> 0 | I14: =IF(H14=0,"",VLOOKUP(H14,Datos!$B$2:$D$908,2,FALSE)) | J14: =IF(H14=0,"",VLOOKUP(H14,Datos!$B$2:$D$908,3,FALSE)) | K14: ='INVENTARIO INICIAL'!K14 -> 0 | L14: ='INVENTARIO INICIAL'!L14 -> 0 | M14: ='INVENTARIO INICIAL'!M14 -> 0 | N14: ='INVENTARIO INICIAL'!N14 -> 0 | O14: ='INVENTARIO INICIAL'!O14 -> 0 | P14: ='INVENTARIO INICIAL'!P14 -> 0 | Q14: ='INVENTARIO INICIAL'!Q14 -> 0 | R14: ='INVENTARIO INICIAL'!R14 -> 0 | S14: ='Reporte Marzo 2026'!AF14 -> 0 | AF14: =IF(AI14>=AJ14,IF(AK14>=0,IF(AJ14>=0,AK14,"Error"))) -> 0 | AG14: ='Reporte Marzo 2026'!AG14 -> 0 | AH14: =AF14*AG14 -> 0 | AI14: =S14+T14 -> 0 | AJ14: =U14+V14+W14+X14+Y14+AB14 -> 0 | AK14: =AI14-AJ14 -> 0 | AL14: Junio | AN14: ='INVENTARIO INICIAL'!X14 -> 0
A15: ='Reporte Marzo 2026'!A15 -> Inventario | B15: ='INVENTARIO INICIAL'!B15 -> 0 | C15: =IF(B15=0,"",VLOOKUP(B15,Datos!$H$2:$K$39,2,FALSE)) | D15: =IF(B15=0,"",VLOOKUP(B15,Datos!$H$2:$K$39,3,FALSE)) | E15: =IF(B15=0,"",VLOOKUP(B15,Datos!$H$2:$K$39,4,FALSE)) | F15: ='INVENTARIO INICIAL'!F15 -> 0 | G15: ='INVENTARIO INICIAL'!G15 -> 0 | H15: ='INVENTARIO INICIAL'!H15 -> 0 | I15: =IF(H15=0,"",VLOOKUP(H15,Datos!$B$2:$D$908,2,FALSE)) | J15: =IF(H15=0,"",VLOOKUP(H15,Datos!$B$2:$D$908,3,FALSE)) | K15: ='INVENTARIO INICIAL'!K15 -> 0 | L15: ='INVENTARIO INICIAL'!L15 -> 0 | M15: ='INVENTARIO INICIAL'!M15 -> 0 | N15: ='INVENTARIO INICIAL'!N15 -> 0 | O15: ='INVENTARIO INICIAL'!O15 -> 0 | P15: ='INVENTARIO INICIAL'!P15 -> 0 | Q15: ='INVENTARIO INICIAL'!Q15 -> 0 | R15: ='INVENTARIO INICIAL'!R15 -> 0 | S15: ='Reporte Marzo 2026'!AF15 -> 0 | AF15: =IF(AI15>=AJ15,IF(AK15>=0,IF(AJ15>=0,AK15,"Error"))) -> 0 | AG15: ='Reporte Marzo 2026'!AG15 -> 0 | AH15: =AF15*AG15 -> 0 | AI15: =S15+T15 -> 0 | AJ15: =U15+V15+W15+X15+Y15+AB15 -> 0 | AK15: =AI15-AJ15 -> 0 | AL15: Junio | AN15: ='INVENTARIO INICIAL'!X15 -> 0
A16: ='Reporte Marzo 2026'!A16 -> Inventario | B16: ='INVENTARIO INICIAL'!B16 -> 0 | C16: =IF(B16=0,"",VLOOKUP(B16,Datos!$H$2:$K$39,2,FALSE)) | D16: =IF(B16=0,"",VLOOKUP(B16,Datos!$H$2:$K$39,3,FALSE)) | E16: =IF(B16=0,"",VLOOKUP(B16,Datos!$H$2:$K$39,4,FALSE)) | F16: ='INVENTARIO INICIAL'!F16 -> 0 | G16: ='INVENTARIO INICIAL'!G16 -> 0 | H16: ='INVENTARIO INICIAL'!H16 -> 0 | I16: =IF(H16=0,"",VLOOKUP(H16,Datos!$B$2:$D$908,2,FALSE)) | J16: =IF(H16=0,"",VLOOKUP(H16,Datos!$B$2:$D$908,3,FALSE)) | K16: ='INVENTARIO INICIAL'!K16 -> 0 | L16: ='INVENTARIO INICIAL'!L16 -> 0 | M16: ='INVENTARIO INICIAL'!M16 -> 0 | N16: ='INVENTARIO INICIAL'!N16 -> 0 | O16: ='INVENTARIO INICIAL'!O16 -> 0 | P16: ='INVENTARIO INICIAL'!P16 -> 0 | Q16: ='INVENTARIO INICIAL'!Q16 -> 0 | R16: ='INVENTARIO INICIAL'!R16 -> 0 | S16: ='Reporte Marzo 2026'!AF16 -> 0 | AF16: =IF(AI16>=AJ16,IF(AK16>=0,IF(AJ16>=0,AK16,"Error"))) -> 0 | AG16: ='Reporte Marzo 2026'!AG16 -> 0 | AH16: =AF16*AG16 -> 0 | AI16: =S16+T16 -> 0 | AJ16: =U16+V16+W16+X16+Y16+AB16 -> 0 | AK16: =AI16-AJ16 -> 0 | AL16: Junio | AN16: ='INVENTARIO INICIAL'!X16 -> 0
A17: ='Reporte Marzo 2026'!A17 -> Inventario | B17: ='INVENTARIO INICIAL'!B17 -> 0 | C17: =IF(B17=0,"",VLOOKUP(B17,Datos!$H$2:$K$39,2,FALSE)) | D17: =IF(B17=0,"",VLOOKUP(B17,Datos!$H$2:$K$39,3,FALSE)) | E17: =IF(B17=0,"",VLOOKUP(B17,Datos!$H$2:$K$39,4,FALSE)) | F17: ='INVENTARIO INICIAL'!F17 -> 0 | G17: ='INVENTARIO INICIAL'!G17 -> 0 | H17: ='INVENTARIO INICIAL'!H17 -> 0 | I17: =IF(H17=0,"",VLOOKUP(H17,Datos!$B$2:$D$908,2,FALSE)) | J17: =IF(H17=0,"",VLOOKUP(H17,Datos!$B$2:$D$908,3,FALSE)) | K17: ='INVENTARIO INICIAL'!K17 -> 0 | L17: ='INVENTARIO INICIAL'!L17 -> 0 | M17: ='INVENTARIO INICIAL'!M17 -> 0 | N17: ='INVENTARIO INICIAL'!N17 -> 0 | O17: ='INVENTARIO INICIAL'!O17 -> 0 | P17: ='INVENTARIO INICIAL'!P17 -> 0 | Q17: ='INVENTARIO INICIAL'!Q17 -> 0 | R17: ='INVENTARIO INICIAL'!R17 -> 0 | S17: ='Reporte Marzo 2026'!AF17 -> 0 | AF17: =IF(AI17>=AJ17,IF(AK17>=0,IF(AJ17>=0,AK17,"Error"))) -> 0 | AG17: ='Reporte Marzo 2026'!AG17 -> 0 | AH17: =AF17*AG17 -> 0 | AI17: =S17+T17 -> 0 | AJ17: =U17+V17+W17+X17+Y17+AB17 -> 0 | AK17: =AI17-AJ17 -> 0 | AL17: Junio | AN17: ='INVENTARIO INICIAL'!X17 -> 0
A18: ='Reporte Marzo 2026'!A18 -> Inventario | B18: ='INVENTARIO INICIAL'!B18 -> 0 | C18: =IF(B18=0,"",VLOOKUP(B18,Datos!$H$2:$K$39,2,FALSE)) | D18: =IF(B18=0,"",VLOOKUP(B18,Datos!$H$2:$K$39,3,FALSE)) | E18: =IF(B18=0,"",VLOOKUP(B18,Datos!$H$2:$K$39,4,FALSE)) | F18: ='INVENTARIO INICIAL'!F18 -> 0 | G18: ='INVENTARIO INICIAL'!G18 -> 0 | H18: ='INVENTARIO INICIAL'!H18 -> 0 | I18: =IF(H18=0,"",VLOOKUP(H18,Datos!$B$2:$D$908,2,FALSE)) | J18: =IF(H18=0,"",VLOOKUP(H18,Datos!$B$2:$D$908,3,FALSE)) | K18: ='INVENTARIO INICIAL'!K18 -> 0 | L18: ='INVENTARIO INICIAL'!L18 -> 0 | M18: ='INVENTARIO INICIAL'!M18 -> 0 | N18: ='INVENTARIO INICIAL'!N18 -> 0 | O18: ='INVENTARIO INICIAL'!O18 -> 0 | P18: ='INVENTARIO INICIAL'!P18 -> 0 | Q18: ='INVENTARIO INICIAL'!Q18 -> 0 | R18: ='INVENTARIO INICIAL'!R18 -> 0 | S18: ='Reporte Marzo 2026'!AF18 -> 0 | AF18: =IF(AI18>=AJ18,IF(AK18>=0,IF(AJ18>=0,AK18,"Error"))) -> 0 | AG18: ='Reporte Marzo 2026'!AG18 -> 0 | AH18: =AF18*AG18 -> 0 | AI18: =S18+T18 -> 0 | AJ18: =U18+V18+W18+X18+Y18+AB18 -> 0 | AK18: =AI18-AJ18 -> 0 | AL18: Junio | AN18: ='INVENTARIO INICIAL'!X18 -> 0
... A360: ='Reporte Marzo 2026'!A360 -> Inventario | B360: ='INVENTARIO INICIAL'!B360 -> 0 | C360: =IF(B360=0,"",VLOOKUP(B360,Datos!$H$2:$K$39,2,FALSE)) | D360: =IF(B360=0,"",VLOOKUP(B360,Datos!$H$2:$K$39,3,FALSE)) | E360: =IF(B360=0,"",VLOOKUP(B360,Datos!$H$2:$K$39,4,FALSE)) | F360: ='INVENTARIO INICIAL'!F360 -> 0 | G360: ='INVENTARIO INICIAL'!G360 -> 0 | H360: ='INVENTARIO INICIAL'!H360 -> 0 | I360: =IF(H360=0,"",VLOOKUP(H360,Datos!$B$2:$D$908,2,FALSE)) | J360: =IF(H360=0,"",VLOOKUP(H360,Datos!$B$2:$D$908,3,FALSE)) | K360: ='INVENTARIO INICIAL'!K360 -> 0 | L360: ='INVENTARIO INICIAL'!L360 -> 0 | M360: ='INVENTARIO INICIAL'!M360 -> 0 | N360: ='INVENTARIO INICIAL'!N360 -> 0 | O360: ='INVENTARIO INICIAL'!O360 -> 0 | P360: ='INVENTARIO INICIAL'!P360 -> 0 | Q360: ='INVENTARIO INICIAL'!Q360 -> 0 | R360: ='INVENTARIO INICIAL'!R360 -> 0 | S360: ='Reporte Marzo 2026'!AF360 -> 0 | AF360: =IF(AI360>=AJ360,IF(AK360>=0,IF(AJ360>=0,AK360,"Error"))) -> 0 | AG360: ='Reporte Marzo 2026'!AG360 -> 0 | AH360: =AF360*AG360 -> 0 | AI360: =S360+T360 -> 0 | AJ360: =U360+V360+W360+X360+Y360+AB360 -> 0 | AK360: =AI360-AJ360 -> 0 | AL360: Junio | AN360: ='INVENTARIO INICIAL'!X360 -> 0
A361: ='Reporte Marzo 2026'!A361 -> Ingresos | B361: ='Reporte Marzo 2026'!B361 -> 0 | C361: =IF(B361=0,"",VLOOKUP(B361,Datos!$H$2:$K$39,2,FALSE)) | D361: =IF(B361=0,"",VLOOKUP(B361,Datos!$H$2:$K$39,3,FALSE)) | E361: =IF(B361=0,"",VLOOKUP(B361,Datos!$H$2:$K$39,4,FALSE)) | F361: ='Reporte Marzo 2026'!F361 -> 0 | G361: ='Reporte Marzo 2026'!G361 -> 0 | H361: ='Reporte Marzo 2026'!H361 -> 0 | I361: =IF(H361=0,"",VLOOKUP(H361,Datos!$B$2:$D$891,2,FALSE)) | J361: =IF(H361=0,"",VLOOKUP(H361,Datos!$B$2:$D$891,3,FALSE)) | K361: ='Reporte Marzo 2026'!K361 -> 0 | L361: ='Reporte Marzo 2026'!L361 -> 0 | M361: ='Reporte Marzo 2026'!M361 -> 0 | N361: ='Reporte Marzo 2026'!N361 -> 0 | O361: ='Reporte Marzo 2026'!O361 -> 0 | P361: ='Reporte Marzo 2026'!P361 -> 0 | Q361: ='Reporte Marzo 2026'!Q361 -> 0 | R361: ='Reporte Marzo 2026'!R361 -> 0 | S361: ='Reporte Marzo 2026'!AF361 -> 0 | AF361: =IF(AI361>=AJ361,IF(AK361>=0,IF(AJ361>=0,AK361,"Error"))) -> 0 | AG361: ='Reporte Marzo 2026'!AG361 -> 0 | AH361: =AF361*AG361 -> 0 | AI361: =S361+T361 -> 0 | AJ361: =U361+V361+W361+X361+Y361+AB361 -> 0 | AK361: =AI361-AJ361 -> 0 | AL361: Junio | AN361: ='Reporte Marzo 2026'!AN361 -> 0
A362: ='Reporte Marzo 2026'!A362 -> Ingresos | B362: ='Reporte Marzo 2026'!B362 -> 0 | C362: =IF(B362=0,"",VLOOKUP(B362,Datos!$H$2:$K$39,2,FALSE)) | D362: =IF(B362=0,"",VLOOKUP(B362,Datos!$H$2:$K$39,3,FALSE)) | E362: =IF(B362=0,"",VLOOKUP(B362,Datos!$H$2:$K$39,4,FALSE)) | F362: ='Reporte Marzo 2026'!F362 -> 0 | G362: ='Reporte Marzo 2026'!G362 -> 0 | H362: ='Reporte Marzo 2026'!H362 -> 0 | I362: =IF(H362=0,"",VLOOKUP(H362,Datos!$B$2:$D$891,2,FALSE)) | J362: =IF(H362=0,"",VLOOKUP(H362,Datos!$B$2:$D$891,3,FALSE)) | K362: ='Reporte Marzo 2026'!K362 -> 0 | L362: ='Reporte Marzo 2026'!L362 -> 0 | M362: ='Reporte Marzo 2026'!M362 -> 0 | N362: ='Reporte Marzo 2026'!N362 -> 0 | O362: ='Reporte Marzo 2026'!O362 -> 0 | P362: ='Reporte Marzo 2026'!P362 -> 0 | Q362: ='Reporte Marzo 2026'!Q362 -> 0 | R362: ='Reporte Marzo 2026'!R362 -> 0 | S362: ='Reporte Marzo 2026'!AF362 -> 0 | AF362: =IF(AI362>=AJ362,IF(AK362>=0,IF(AJ362>=0,AK362,"Error"))) -> 0 | AG362: ='Reporte Marzo 2026'!AG362 -> 0 | AH362: =AF362*AG362 -> 0 | AI362: =S362+T362 -> 0 | AJ362: =U362+V362+W362+X362+Y362+AB362 -> 0 | AK362: =AI362-AJ362 -> 0 | AL362: Junio | AN362: ='Reporte Marzo 2026'!AN362 -> 0
