Workbook
Name destino_plantas: DATOS!#REF!
Name DESTINO_U_OBJETIVO_DE_LA_PRODUCCIÓN: DATOS!$Q$2:$Q$16
Name Nombre_cientifico: DATOS!$B$2:$B$890
Name NOMBRE_DE_VIVERO__CENTRO_DE_ACONDICIONAMIENTO_O_ACOPIO: DATOS!$H$2:$H$49
Name Pograma_Producción2020: #REF!
Name Región_de_Antofagasta: 'Comunas y regiones'!$H$3:$H$54
Name Región_de_Arica_y_Parinacota: 'Comunas y regiones'!$F$3:$F$54
Name Región_de_Atacama: 'Comunas y regiones'!$I$3:$I$54
Name Región_de_Aysén_del_Gral_C_Ibáñez_del_Campo: 'Comunas y regiones'!$S$3:$S$54
Name Región_de_Coquimbo: 'Comunas y regiones'!$J$3:$J$54
Name Región_de_La_Araucanía: 'Comunas y regiones'!$P$3:$P$54
Name Región_de_Los_Lagos: 'Comunas y regiones'!$R$3:$R$54
Name Región_de_Los_Ríos: 'Comunas y regiones'!$Q$3:$Q$54
Name Región_de_Magallanes_y_de_La_Antártica_Chilena: 'Comunas y regiones'!$T$3:$T$54
Name Región_de_Ñuble: 'Comunas y regiones'!$O$3:$O$54
Name Región_de_Tarapacá: 'Comunas y regiones'!$G$3:$G$54
Name Región_de_Valparaíso: 'Comunas y regiones'!$K$3:$K$54
Name Región_deArica_y_Parinacota: 'Comunas y regiones'!$C$4:$D$4
Name Región_del_Bíobío: 'Comunas y regiones'!$N$3:$N$54
Name Región_del_Libertador_B_O_Higgins: 'Comunas y regiones'!$L$3:$L$54
Name Región_del_Maule: 'Comunas y regiones'!$M$3:$M$54
Name Región_Metropolitana_de_Santiago: 'Comunas y regiones'!$U$3:$U$54
Name Regiones_Chile: 'Comunas y regiones'!$F$2:$U$2
Name TIPO_DE_CONTENEDOR: DATOS!$O$2:$O$7
Name TIPO_DE_REPRODUCCIÓN: DATOS!$N$2:$N$3
Name Uso: DATOS!#REF!
Name Usuario: DATOS!#REF!

Sheet Ingreso Datos
B1: PROGRAMA DE PRODUCCIÓN Y EVALUACIÓN DE PLANTAS, SIGI GBCC 8 2026 | AK1: *INFORMACIÓN A ENTREGAR EN DICIEMBRE 2026
B2: Antecedentes Administrativos | H2: Objetivo Plantas | I2: COLECTA DE SEMILLAS O MATERIAL DE PROPAGACIÓN | V2: Procesos de la Semillas | AA2: Análisis de Semillas | AF2: Siembra de la Semillas | AK2: Manejo del Almacigo (Siembra)
B3: Unidad Productiva | C3: Regiones | D3: Provincia | E3: Comuna | F3: Encargado (a) del Vivero | G3: Teléfono de Contacto | H3: Programas de Destino | I3: Nombre científico | J3: Nombre Común | K3: Origen | L3: Fuentes de Abastecimiento del Material de Propagación | M3: Fecha de Colecta | N3: Lugar de Colecta (Localidad) | O3: Comuna de Colecta | P3: Huso | Q3: Coordenadas X | R3: Coordenadas Y | S3: Cantidad (Semillas / Material Vegetativo) | T3: Unidad de Medida | U3: Forma de Colecta | V3: Secado | W3: Limpieza / Selección | X3: Almacenaje | Y3: Tratamientos Pregerminativos | Z3: Producción Estimada (N° total de plantas) (Np) | AA3: Análisis de Muestras de Semillas | AB3: Nº semillas / kg (según especie) (Ns) | AC3: Pg | AD3: Pv | AE3: Ps | AF3: Cantidad (Semillas Sembrar / M.V. a Instalar) S (kg) | AG3: Unidades | AH3: Fecha Siembra | AI3: Tipo de Siembra | AJ3: Tipo Sustrato (siembra) | AK3: Tipo de Aplicación | AL3: N° de Aplicaciones | AM3: Productos Fitosanitarios | AN3: Dosis (gr/L- cc/L) | AO3: Frecuencia Semanal | AP3: Tipo de Riego | AQ3: Nº Semillas Sembradas (parcela ensayo) | AR3: Fecha Inicio Germinación (Control 1) | AS3: Fecha Evaluación Emergencia (Control 2) | AT3: Nº Plántulas Emergidas (Control 2) | AU3: Fecha Término Evaluación Emergencia (Control 3) | AV3: Nº Total Plantúlas Emergidas (Control 3) | AW3: Porcentaje Germinación (Pg ) | AX3: Porcentaje No Germinación (%) | AY3: Causas del Porcentaje de no Germinación, Muertes y/o Pérdidas | AZ3: Fecha del Repique | BA3: Nº Plantas Repicadas | BB3: N° Total de Plantas Ingresadas a Inventario (un mes post repique) | BC3: Factor de Viverización (Ps) | BD3: OBSERVACIONES GENERALES DEL PROCESO DE PRODUCCIÓN
B5: Vivero Centro de Semillas, Genética y Entomología | C5: =IF(B5=0,"",VLOOKUP(B5,DATOS!$H$2:$K$50,2,FALSE)) -> Región de Ñuble - Centro de Semillas, Genética y Entomología | D5: =IF(B5=0,"",VLOOKUP(B5,DATOS!$H$2:$L$49,3,FALSE)) -> Diguillin | E5: =IF(B5=0,"",VLOOKUP(B5,DATOS!$H$2:$M$49,4,FALSE)) -> Chillán | F5: Juan Contreras C. | G5: 56 9 8596 1236 | H5: Programa de Arborización | I5: Zinnia sp. | J5: =IF(I5=0,"",VLOOKUP(I5,DATOS!$B$2:$D$891,2,FALSE)) -> Zinnia sp. | K5: =IF(I5=0,"",VLOOKUP(I5,DATOS!$B$2:$D$891,3,FALSE)) -> Exótico | L5: Gestión propia | M5: 45911 | N5: China Muerta | O5: Lonquimay | P5: 18 | Q5: 680444 | R5: 5708084 | S5: 1000 | T5: Kilos | U5: Cosecha manual directa | V5: Al aire Libre | W5: Manual | X5: En cámara de frio | Y5: Estratificación fría en arena húmeda | Z5: 10000 | AA5: En laboratorio de semillas | AB5: 5000 | AC5: 0.9 | AD5: 0.8 | AE5: 0.9 | AF5: 2.92 | AG5: Kilos | AH5: 46266 | AI5: Almacigueras | AJ5: Compost | AK5: Fungicida | AL5: 5 | AM5: Capta + Polyben | AN5: 2 y 1,5 | AO5: 2 | AP5: Manual | AQ5: 100 | AR5: 45981 | AS5: 45960 | AT5: 0.9 | AU5: 46037 | AV5: 0.95 | AW5: 0.5 | AX5: 0.5 | AY5: Ataques de gusanos cortadores | AZ5: 46052 | BA5: 4000 | BB5: 2500 | BC5: =IFERROR(IF(BA5<=0, 0,IF(BA5=0,0,(1-BB5/BA5))),0) -> 0.375
B6: Vivero Alejandro Caipa | C6: =IF(B6=0,"",VLOOKUP(B6,DATOS!$H$2:$K$50,2,FALSE)) -> Región de Tarapacá | D6: =IF(B6=0,"",VLOOKUP(B6,DATOS!$H$2:$L$49,3,FALSE)) -> Tamarugal | E6: =IF(B6=0,"",VLOOKUP(B6,DATOS!$H$2:$M$49,4,FALSE)) -> Pozo Almonte | F6: Luis Ayala J. | G6: 56 2 2663 6666 | H6: Bosque Nativo | J6: =IF(I6=0,"",VLOOKUP(I6,DATOS!$B$2:$D$891,2,FALSE)) | K6: =IF(I6=0,"",VLOOKUP(I6,DATOS!$B$2:$D$891,3,FALSE)) | T6: Plántulas Reg.natural | BC6: =IFERROR(IF(BA6<=0, 0,IF(BA6=0,0,(1-BB6/BA6))),0) -> 0
B7: Vivero Regional Antofagasta | C7: =IF(B7=0,"",VLOOKUP(B7,DATOS!$H$2:$K$50,2,FALSE)) -> Región de Antofagasta | D7: =IF(B7=0,"",VLOOKUP(B7,DATOS!$H$2:$L$49,3,FALSE)) -> Antofagasta | E7: =IF(B7=0,"",VLOOKUP(B7,DATOS!$H$2:$M$49,4,FALSE)) -> Antofagasta | F7: Ana Paredes A. | G7: 56 4 1253 9654 | H7: Programa de Reactivación Económica Forestal | J7: =IF(I7=0,"",VLOOKUP(I7,DATOS!$B$2:$D$891,2,FALSE)) | K7: =IF(I7=0,"",VLOOKUP(I7,DATOS!$B$2:$D$891,3,FALSE)) | BC7: =IFERROR(IF(BA7<=0, 0,IF(BA7=0,0,(1-BB7/BA7))),0) -> 0
C8: =IF(B8=0,"",VLOOKUP(B8,DATOS!$H$2:$K$50,2,FALSE)) | D8: =IF(B8=0,"",VLOOKUP(B8,DATOS!$H$2:$L$49,3,FALSE)) | E8: =IF(B8=0,"",VLOOKUP(B8,DATOS!$H$2:$M$49,4,FALSE)) | J8: =IF(I8=0,"",VLOOKUP(I8,DATOS!$B$2:$D$891,2,FALSE)) | K8: =IF(I8=0,"",VLOOKUP(I8,DATOS!$B$2:$D$891,3,FALSE)) | BC8: =IFERROR(IF(BA8<=0, 0,IF(BA8=0,0,(1-BB8/BA8))),0) -> 0
C9: =IF(B9=0,"",VLOOKUP(B9,DATOS!$H$2:$K$50,2,FALSE)) | D9: =IF(B9=0,"",VLOOKUP(B9,DATOS!$H$2:$L$49,3,FALSE)) | E9: =IF(B9=0,"",VLOOKUP(B9,DATOS!$H$2:$M$49,4,FALSE)) | J9: =IF(I9=0,"",VLOOKUP(I9,DATOS!$B$2:$D$891,2,FALSE)) | K9: =IF(I9=0,"",VLOOKUP(I9,DATOS!$B$2:$D$891,3,FALSE)) | BC9: =IFERROR(IF(BA9<=0, 0,IF(BA9=0,0,(1-BB9/BA9))),0) -> 0
C10: =IF(B10=0,"",VLOOKUP(B10,DATOS!$H$2:$K$50,2,FALSE)) | D10: =IF(B10=0,"",VLOOKUP(B10,DATOS!$H$2:$L$49,3,FALSE)) | E10: =IF(B10=0,"",VLOOKUP(B10,DATOS!$H$2:$M$49,4,FALSE)) | J10: =IF(I10=0,"",VLOOKUP(I10,DATOS!$B$2:$D$891,2,FALSE)) | K10: =IF(I10=0,"",VLOOKUP(I10,DATOS!$B$2:$D$891,3,FALSE)) | BC10: =IFERROR(IF(BA10<=0, 0,IF(BA10=0,0,(1-BB10/BA10))),0) -> 0
C11: =IF(B11=0,"",VLOOKUP(B11,DATOS!$H$2:$K$50,2,FALSE)) | D11: =IF(B11=0,"",VLOOKUP(B11,DATOS!$H$2:$L$49,3,FALSE)) | E11: =IF(B11=0,"",VLOOKUP(B11,DATOS!$H$2:$M$49,4,FALSE)) | J11: =IF(I11=0,"",VLOOKUP(I11,DATOS!$B$2:$D$891,2,FALSE)) | K11: =IF(I11=0,"",VLOOKUP(I11,DATOS!$B$2:$D$891,3,FALSE)) | BC11: =IFERROR(IF(BA11<=0, 0,IF(BA11=0,0,(1-BB11/BA11))),0) -> 0
C12: =IF(B12=0,"",VLOOKUP(B12,DATOS!$H$2:$K$50,2,FALSE)) | D12: =IF(B12=0,"",VLOOKUP(B12,DATOS!$H$2:$L$49,3,FALSE)) | E12: =IF(B12=0,"",VLOOKUP(B12,DATOS!$H$2:$M$49,4,FALSE)) | J12: =IF(I12=0,"",VLOOKUP(I12,DATOS!$B$2:$D$891,2,FALSE)) | K12: =IF(I12=0,"",VLOOKUP(I12,DATOS!$B$2:$D$891,3,FALSE)) | BC12: =IFERROR(IF(BA12<=0, 0,IF(BA12=0,0,(1-BB12/BA12))),0) -> 0
C13: =IF(B13=0,"",VLOOKUP(B13,DATOS!$H$2:$K$50,2,FALSE)) | D13: =IF(B13=0,"",VLOOKUP(B13,DATOS!$H$2:$L$49,3,FALSE)) | E13: =IF(B13=0,"",VLOOKUP(B13,DATOS!$H$2:$M$49,4,FALSE)) | J13: =IF(I13=0,"",VLOOKUP(I13,DATOS!$B$2:$D$891,2,FALSE)) | K13: =IF(I13=0,"",VLOOKUP(I13,DATOS!$B$2:$D$891,3,FALSE)) | BC13: =IFERROR(IF(BA13<=0, 0,IF(BA13=0,0,(1-BB13/BA13))),0) -> 0
C14: =IF(B14=0,"",VLOOKUP(B14,DATOS!$H$2:$K$50,2,FALSE)) | D14: =IF(B14=0,"",VLOOKUP(B14,DATOS!$H$2:$L$49,3,FALSE)) | E14: =IF(B14=0,"",VLOOKUP(B14,DATOS!$H$2:$M$49,4,FALSE)) | J14: =IF(I14=0,"",VLOOKUP(I14,DATOS!$B$2:$D$891,2,FALSE)) | K14: =IF(I14=0,"",VLOOKUP(I14,DATOS!$B$2:$D$891,3,FALSE)) | BC14: =IFERROR(IF(BA14<=0, 0,IF(BA14=0,0,(1-BB14/BA14))),0) -> 0
C15: =IF(B15=0,"",VLOOKUP(B15,DATOS!$H$2:$K$50,2,FALSE)) | D15: =IF(B15=0,"",VLOOKUP(B15,DATOS!$H$2:$L$49,3,FALSE)) | E15: =IF(B15=0,"",VLOOKUP(B15,DATOS!$H$2:$M$49,4,FALSE)) | J15: =IF(I15=0,"",VLOOKUP(I15,DATOS!$B$2:$D$891,2,FALSE)) | K15: =IF(I15=0,"",VLOOKUP(I15,DATOS!$B$2:$D$891,3,FALSE)) | BC15: =IFERROR(IF(BA15<=0, 0,IF(BA15=0,0,(1-BB15/BA15))),0) -> 0
C16: =IF(B16=0,"",VLOOKUP(B16,DATOS!$H$2:$K$50,2,FALSE)) | D16: =IF(B16=0,"",VLOOKUP(B16,DATOS!$H$2:$L$49,3,FALSE)) | E16: =IF(B16=0,"",VLOOKUP(B16,DATOS!$H$2:$M$49,4,FALSE)) | J16: =IF(I16=0,"",VLOOKUP(I16,DATOS!$B$2:$D$891,2,FALSE)) | K16: =IF(I16=0,"",VLOOKUP(I16,DATOS!$B$2:$D$891,3,FALSE)) | BC16: =IFERROR(IF(BA16<=0, 0,IF(BA16=0,0,(1-BB16/BA16))),0) -> 0
C17: =IF(B17=0,"",VLOOKUP(B17,DATOS!$H$2:$K$50,2,FALSE)) | D17: =IF(B17=0,"",VLOOKUP(B17,DATOS!$H$2:$L$49,3,FALSE)) | E17: =IF(B17=0,"",VLOOKUP(B17,DATOS!$H$2:$M$49,4,FALSE)) | J17: =IF(I17=0,"",VLOOKUP(I17,DATOS!$B$2:$D$891,2,FALSE)) | K17: =IF(I17=0,"",VLOOKUP(I17,DATOS!$B$2:$D$891,3,FALSE)) | BC17: =IFERROR(IF(BA17<=0, 0,IF(BA17=0,0,(1-BB17/BA17))),0) -> 0
C18: =IF(B18=0,"",VLOOKUP(B18,DATOS!$H$2:$K$50,2,FALSE)) | D18: =IF(B18=0,"",VLOOKUP(B18,DATOS!$H$2:$L$49,3,FALSE)) | E18: =IF(B18=0,"",VLOOKUP(B18,DATOS!$H$2:$M$49,4,FALSE)) | J18: =IF(I18=0,"",VLOOKUP(I18,DATOS!$B$2:$D$891,2,FALSE)) | K18: =IF(I18=0,"",VLOOKUP(I18,DATOS!$B$2:$D$891,3,FALSE)) | BC18: =IFERROR(IF(BA18<=0, 0,IF(BA18=0,0,(1-BB18/BA18))),0) -> 0
C19: =IF(B19=0,"",VLOOKUP(B19,DATOS!$H$2:$K$50,2,FALSE)) | D19: =IF(B19=0,"",VLOOKUP(B19,DATOS!$H$2:$L$49,3,FALSE)) | E19: =IF(B19=0,"",VLOOKUP(B19,DATOS!$H$2:$M$49,4,FALSE)) | J19: =IF(I19=0,"",VLOOKUP(I19,DATOS!$B$2:$D$891,2,FALSE)) | K19: =IF(I19=0,"",VLOOKUP(I19,DATOS!$B$2:$D$891,3,FALSE)) | BC19: =IFERROR(IF(BA19<=0, 0,IF(BA19=0,0,(1-BB19/BA19))),0) -> 0
... C32: =IF(B32=0,"",VLOOKUP(B32,DATOS!$H$2:$K$50,2,FALSE)) | D32: =IF(B32=0,"",VLOOKUP(B32,DATOS!$H$2:$L$49,3,FALSE)) | E32: =IF(B32=0,"",VLOOKUP(B32,DATOS!$H$2:$M$49,4,FALSE)) | J32: =IF(I32=0,"",VLOOKUP(I32,DATOS!$B$2:$D$891,2,FALSE)) | K32: =IF(I32=0,"",VLOOKUP(I32,DATOS!$B$2:$D$891,3,FALSE)) | BC32: =IFERROR(IF(BA32<=0, 0,IF(BA32=0,0,(1-BB32/BA32))),0) -> 0
Z33: =SUM(Z5:Z32) -> 10000 | BA33: =SUM(BA5:BA32) -> 4000 | BB33: =SUM(BB5:BB32) -> 2500 | BC33: =IFERROR(IF(BA33<=0, 0,IF(BA33=0,0,(1-BB33/BA33))),0) -> 0.375

Sheet DATOS
A1: N | B1: Nombre Científico | C1: Nombre Común | D1: Origen | E1: Hábito | G1: N° | H1: VIVERO, CENTRO DE ACONDICIONAMIENTO O ACOPIO | I1: UNIDAD ADMINISTRATIVA | J1: PROVINCIA | K1: COMUNA | M1: TIPO DE RIEGO | N1: TIPO DE REPRODUCCIÓN | O1: TIPO DE CONTENEDOR | S1: Tratamientos pregerminativos
A2: 1 | B2: Abelia x grandiflora | C2: Abelia | D2: Exótico | E2: Arbustivo | G2: 1 | H2: Vivero Las Maitas | I2: Región de Arica y Parinacota | J2: Arica | K2: Arica | M2: Manual | N2: Semilla | O2: Almácigo | Q2: Secado semillas | S2: Lixiviación Remojo en agua | U2: DESTINO DE PLANTAS
A3: 2 | B3: Abies alba | C3: Abeto blanco / Abeto común | D3: Exótico | E3: Arbóreo | G3: 2 | H3: Vivero Putre | I3: Región de Arica y Parinacota | J3: Parinacota | K3: Putre | M3: Aspersión | N3: Vegetativa | O3: Bandeja_Speedling | Q3: Al aire Libre | S3: Escarificación física | U3: Áreas Silvestres Protegidas
A4: 3 | B4: Abutilon incanum | C4: Pelotazo / Tronadora | D4: Exótico | E4: Arbustivo | G4: 3 | H4: Vivero Alejandro Caipa | I4: Región de Tarapacá | J4: Tamarugal | K4: Pozo Almonte | M4: Mixto | O4: Bandeja_Tubetes | Q4: Cámara de secado | S4: Escarificación mecánica | U4: Bosque Nativo
A5: 4 | B5: Abutilon sp. | C5: Abutilón | D5: Exótico | E5: Arbustivo | G5: 4 | H5: Vivero Regional Antofagasta | I5: Región de Antofagasta | J5: Antofagasta | K5: Antofagasta | M5: Microaspersión | O5: Bolsas | Q5: En bodega calefaccionada | S5: No requiere tratamiento | U5: Compensación R. N. Pampa del Tamarugal
A6: 5 | B6: Abutilon striatum | C6: Abutilón | D6: Exótico | E6: Arbustivo | G6: 5 | H6: Vivero Quillagua | I6: Región de Antofagasta | J6: Tocopilla | K6: María Elena | O6: Raíz_Desnuda | S6: Remojo en Ácido giberelico | U6: Conservación
A7: 6 | B7: Acacia caven / Vachellia caven | C7: Espino | D7: Nativo | E7: Arbóreo | G7: 6 | H7: Vivero Copiapó | I7: Región de Atacama | J7: Copiapó | K7: Copiapó | M7: Unidades medida | O7: Patrik | Q7: Limpieza/selección | S7: Estratificación fría en arena húmeda | U7: Difusión
A8: 7 | B8: Acacia cultriformis | C8: Acacia de hoja de cuchillo | D8: Exótico | E8: Arbustivo | G8: 7 | H8: Vivero Vallenar | I8: Región de Atacama | J8: Huasco | K8: Vallenar | M8: kg | Q8: Manual | S8: Estratificación fría en tierra vegetal | U8: Especies con fines melíferos
A9: 8 | B9: Acacia cyclops | C9: Acacia de costa | D9: Exótico | E9: Arbustivo | G9: 8 | H9: Vivero Illapel | I9: Región de Coquimbo | J9: Choapa | K9: Illapel | M9: n° semillas | O9: Huso | Q9: Mecánica | S9: Almacenamiento en cámara de Frío | U9: Forestación Campesina
A10: 9 | B10: Acacia dealbata | C10: Aromo común | D10: Exótico | E10: Arbóreo | G10: 9 | H10: Vivero Archipiélago Juan Fernández | I10: Región de Valparaíso | J10: Valparaíso | K10: Juan Fernández | M10: gr | O10: 12 | Q10: Otros equipos | S10: Desinfección semillas | U10: Forestación Participativa
A11: 10 | B11: Acacia horrida / Vachellia horrida | C11: Acacia espinosa | D11: Exótico | E11: Arbóreo | G11: 10 | H11: Vivero Reserva Nacional Lago Peñuelas | I11: Región de Valparaíso | J11: Valparaíso | K11: Valparaíso | M11: unidades | O11: 17 | S11: Sin tratamiento. | U11: Germoplasma
A12: 11 | B12: Acacia karroo | C12: Aromo de Sudáfrica | D12: Exótico | E12: Arbóreo | G12: 11 | H12: Vivero La Ligua | I12: Región de Valparaíso | J12: Petorca | K12: La Ligua | M12: estacas | O12: 18 | U12: Plantaciones Forestales
A13: 12 | B13: Acacia koa | C13: Koa | D13: Exótico | E13: Arbóreo | G13: 12 | H13: Vivero Llay Llay | I13: Región de Valparaíso | J13: San Felipe de Aconcagua | K13: Llay Llay | M13: Plántulas Reg.natural | O13: 19 | Q13: Almacenaje | U13: Plantas Gobierno Regional Aysén
A14: 13 | B14: Acacia longifolia | C14: Acacia trinervis | D14: Exótico | E14: Arbóreo | G14: 13 | H14: Vivero Chomedahue | I14: Región del Libertador Gral. Bernardo O'Higgins | J14: Colchagua | K14: Santa Cruz | M14: esquejes | Q14: Abierto | S14: Análisis de las semillas | U14: Programa Castor
A15: 14 | B15: Acacia macracantha | C15: Acacia macacranta | D15: Exótico | E15: Arbóreo | G15: 14 | H15: Centro de Acopio Pantanillo | I15: Región del Maule | J15: Talca | K15: Constitución | M15: Plantas | O15: Forma de la Colecta | Q15: Cálido con control de humedad | U15: Programa de Arborización
A16: 15 | B16: Acacia melanoxylon | C16: Aromo australiano | D16: Exótico | E16: Arbóreo | G16: 15 | H16: Centro Experimental Cauquenes | I16: Región del Maule | J16: Cauquenes | K16: Cauquenes | O16: Cosecha manual directa | Q16: En cámara de frío | S16: En sala de semillas (En el vivero) | U16: Programa Manejo Sustentable de la Tierra (PMST)
A17: 16 | B17: Acacia nilotica / Acacia arabica | C17: Acacia arabiga / Goma arábica | D17: Exótico | E17: Arbóreo | G17: 16 | H17: Base Brigada La Granja | I17: Región del Biobío | J17: Arauco | K17: Cañete | O17: Escalamiento | Q17: Ambiente frío-húmedo | S17: En laboratorio de semillas | U17: Proyecto Conservación Raulí
A18: 17 | B18: Acacia rubida | C18: Zarzo rojo | D18: Exótico | E18: Arbustivo | G18: 17 | H18: Centro de Acondicionamiento Duqueco | I18: Región del Biobío | J18: BioBio | K18: Los Ángeles | O18: Golpe o corte de ramas desde el suelo | Q18: Salas o bodegas | S18: Sin análisis de semillas | U18: Proyecto Plantas Medicinales
A19: 18 | B19: Acacia salicina | C19: Zarzo | D19: Exótico | E19: Arbóreo | G19: 18 | H19: Liceo Nueva Zelandia | I19: Región del Biobío | J19: Concepción | K19: Santa Juana | O19: Instalación de carpa o malla bajo el árbol | Q19: Frízer o refrigerador | U19: Proyectos de Investigación
A20: 19 | B20: Acacia saligna / Acacia cyanophylla | C20: Acacia azul | D20: Exótico | E20: Arbóreo | G20: 19 | H20: Vivero Curacautín | I20: Región de La Araucanía | J20: Malleco | K20: Curacautín | O20: Recolección desde el suelo | U20: Reforestación P. N. Torres del Paine
A21: 20 | B21: Acacia semperflorens | C21: Acacia semperflorens | D21: Exótico | E21: Arbóreo | G21: 20 | H21: Vivero Imperial | I21: Región de La Araucanía | J21: Cautín | K21: Nueva Imperial | O21: Sacudir o golpear las ramas para desprender los frutos o semillas | U21: Restauración
A22: 21 | B22: Acacia senegal | C22: Acacia Senegal | D22: Exótico | E22: Arbóreo | G22: 21 | H22: Vivero Huillilemu | I22: Región de Los Ríos | J22: Valdivia | K22: Mariquina | O22: Selección y corte de estacas o esquejes | U22: Ventas
A23: 22 | B23: Acacia sp. | C23: Acacia | D23: Exótico | E23: Arbóreo | G23: 22 | H23: Vivero San Juan | I23: Región de Los Ríos | J23: Valdivia | K23: Panguipulli | U23: Araucaria
A24: 23 | B24: Acacia tomentosa / Vachellia tomentosa | C24: Acacia | D24: Exótico | E24: Arbóreo | G24: 23 | H24: Vivero Chabranco | I24: Región de Los Ríos | J24: Valdivia | K24: Futrono | O24: Tipo de Abastecimiento | U24: Fondo Verde del Clima
A25: 24 | B25: Acacia victoriae | C25: Gundabluie | D25: Exótico | E25: Arbustivo | G25: 24 | H25: Vivero Liceo Técnico de Ignao | I25: Región de Los Ríos | J25: Ranco | K25: Lago Ranco | O25: Compra | Q25: Tipo de siembra | U25: Programa de Reactivación Económica Forestal
A26: 25 | B26: Acacia visco | C26: Vilca | D26: Exótico | E26: Arbóreo | G26: 25 | H26: Vivero Mashue | I26: Región de Los Ríos | J26: Ranco | K26: La Unión | O26: Donación | Q26: Almacigueras | U26: Otro (especificar en observaciones)
A27: 26 | B27: Acalypha wilkesiana | C27: Acalifa | D27: Exótico | E27: Arbustivo | G27: 26 | H27: Vivero Llancacura | I27: Región de Los Ríos | J27: Ranco | K27: La Unión | O27: Gestión propia | Q27: Cama caliente
A28: 27 | B28: Acer japonicum | C28: Arce japónico | D28: Exótico | E28: Arbóreo | G28: 27 | H28: Vivero Butalcura | I28: Región de Los Lagos | J28: Chiloé | K28: Dalcahue | O28: Traspaso interno de CONAF | Q28: Raíz desnuda | U28: Causas de pérdidas de plantúlas
A29: 28 | B29: Acer negundo | C29: Arce negundo | D29: Exótico | E29: Arbóreo | G29: 28 | H29: Vivero Augusto Falcón | I29: Región de Aysén del Gral. Carlos Ibáñez del Campo | J29: General Carrera | K29: Chile chico | O29: Otro (Especificar en observaciones) | Q29: Siembra directa (bolsa) | U29: Ataques de gusanos cortadores
A30: 29 | B30: Acer palmatum | C30: Arce palmeado japonés | D30: Exótico | E30: Arbóreo | G30: 29 | H30: Centro de Acondicionamiento Cochrane | I30: Región de Aysén del Gral. Carlos Ibáñez del Campo | J30: Capitán Prat | K30: Cochrane | Q30: Siembra directa (bandejas) | U30: Larvas de insectos
A31: 30 | B31: Acer platanoides | C31: Arce de Noruega / Arce real | D31: Exótico | E31: Arbóreo | G31: 30 | H31: Vivero El Mallín | I31: Región de Aysén del Gral. Carlos Ibáñez del Campo | J31: Aysén | K31: Aysén | O31: Unidad de Medida | Q31: Almácigo o semillero | U31: Lagomorfos
A32: 31 | B32: Acer pseudoplatanus | C32: Falso plátano | D32: Exótico | E32: Arbóreo | G32: 31 | H32: Vivero Las Lengas | I32: Región de Aysén del Gral. Carlos Ibáñez del Campo | J32: Coyhaique | K32: Coyhaique | O32: Estacas | U32: Pájaros
A33: 32 | B33: Acer sp. | C33: Acer | D33: Exótico | E33: Arbóreo | G33: 32 | H33: Vivero Dorotea | I33: Región de Magallanes y de La Antártica Chilena | J33: Última Esperanza | K33: Natales | O33: Esquejes | Q33: Tipo de Aplicación | U33: Roedores
A34: 33 | B34: Achillea millefolium | C34: Milenrama | D34: Exótico | E34: Herbáceo | G34: 33 | H34: Vivero Río de Los Ciervos | I34: Región de Magallanes y de La Antártica Chilena | J34: Magallanes | K34: Punta Arenas | O34: N° de semillas | Q34: Acaricida | U34: Hongos del Follaje (Botritis)
A35: 34 | B35: Adesmia balsamica | C35: Jarilla | D35: Nativo Conservación | E35: Arbustivo | G35: 34 | H35: Vivero Buin | I35: Región Metropolitana | J35: Maipo | K35: Buin | O35: Gramos | Q35: Fungicida | U35: Hongos del suelo (dumping off)
A36: 35 | B36: Adesmia confusa | C36: Palhuén / Espinillo / Varilla brava | D36: Nativo | E36: Arbustivo | G36: 35 | H36: Vivero Reserva Nacional Río Clarillo | I36: Región Metropolitana | J36: Cordillera | K36: Pirque | O36: Kilos | Q36: Insecticida | U36: Nemátodos
A37: 36 | B37: Adesmia echinus | C37: Adesmia | D37: Nativo | E37: Arbustivo | G37: 36 | H37: Vivero San Pedro | I37: Región Metropolitana | J37: Melipilla | K37: San Pedro | O37: Plántulas Reg.natural | Q37: Molusquicida | U37: Bacterias
A38: 37 | B38: Adesmia emarginata | C38: Paramela / Paramilla | D38: Nativo | E38: Arbustivo | G38: 37 | H38: Vivero Centro de Semillas, Genética y Entomología | I38: Región de Ñuble - Centro de Semillas, Genética y Entomología | J38: Diguillin | K38: Chillán | O38: Unidad | Q38: Nematicida | U38: Falta de riego
A39: 38 | B39: Adesmia hystrix | C39: Adesmia | D39: Nativo | E39: Arbustivo | G39: 38 | H39: Vivero Mataveri Otai | I39: Isla de Pascua | J39: Isla de Pascua | K39: Isla de Pascua | Q39: No se aplica tratamiento (Explicar en observaciones) | U39: Exceso de riego
A40: 39 | B40: Adesmia loudonia | C40: Adesmia | D40: Nativo | E40: Arbustivo | O40: Tipo material propagación | Q40: Otros (especificar en observaciones) | U40: Calidad de la semilla
...

Sheet Comunas y regiones
A2: Nº | B2: Región | C2: Comunas | D2: Provincia | F2: Región_de_Arica_y_Parinacota | G2: Región_de_Tarapacá | H2: Región_de_Antofagasta | I2: Región_de_Atacama | J2: Región_de_Coquimbo | K2: Región_de_Valparaíso | L2: Región_del_Libertador_B_O'Higgins | M2: Región_del_Maule | N2: Región_del_Bíobío | O2: Región_de_Ñuble | P2: Región_de_La_Araucanía | Q2: Región_de_Los_Ríos | R2: Región_de_Los_Lagos | S2: Región_de_Aysén_del_Gral_C_Ibáñez_del_Campo | T2: Región_de_Magallanes_y_de_La_Antártica_Chilena | U2: Región_Metropolitana_de_Santiago
A3: 1 | B3: Región de Arica y Parinacota | C3: Arica | D3: Arica | F3: Arica | G3: Iquique | H3: Antofagasta | I3: Copiapó | J3: La Serena | K3: Valparaíso | L3: Rancagua | M3: Talca | N3: Concepción | O3: Chillán | P3: Temuco | Q3: Valdivia | R3: Puerto Montt | S3: Coihaique | T3: Punta Arenas | U3: Santiago
A4: 2 | C4: Camarones | D4: Arica | F4: Camarones | G4: Camiña | H4: Mejillones | I4: Caldera | J4: Coquimbo | K4: Casablanca | L4: Codegua | M4: Constitución | N4: Coronel | O4: Bulnes | P4: Carahue | Q4: Corral | R4: Calbuco | S4: Lago Verde | T4: Laguna Blanca | U4: Cerrillos
A5: 3 | C5: Putre | D5: Parinacota | F5: Putre | G5: Colchane | H5: Sierra Gorda | I5: Tierra Amarilla | J5: Andacollo | K5: Concón | L5: Coinco | M5: Curepto | N5: Chiguayante | O5: Cobquecura | P5: Cunco | Q5: Futrono | R5: Cochamó | S5: Aisén | T5: Río Verde | U5: Cerro Navia
A6: 4 | C6: General Lagos | D6: Parinacota | F6: General Lagos | G6: Huara | H6: Taltal | I6: Chañaral | J6: La Higuera | K6: Juan Fernández | L6: Coltauco | M6: Empedrado | N6: Florida | O6: Coelemu | P6: Curarrehue | Q6: La Unión | R6: Fresia | S6: Cisnes | T6: San Gregorio | U6: Conchalí
A7: 5 | B7: Región de Tarapacá | C7: Iquique | D7: Iquique | G7: Pica | H7: Calama | I7: Diego de Almagro | J7: Paiguano | K7: Puchuncaví | L7: Doñihue | M7: Maule | N7: Hualqui | O7: Coihueco | P7: Freire | Q7: Lago Ranco | R7: Frutillar | S7: Guaitecas | T7: Cabo de Hornos | U7: El Bosque
A8: 6 | C8: Camiña | D8: Tamarugal | G8: Pozo Almonte | H8: Ollagüe | I8: Vallenar | J8: Vicuña | K8: Quilpué | L8: Graneros | M8: Pelarco | N8: Lota | O8: Chillán Viejo | P8: Galvarino | Q8: Lanco | R8: Los Muermos | S8: Cochrane | T8: Antártica | U8: Estación Central
A9: 7 | C9: Colchane | D9: Tamarugal | G9: Alto Hospicio | H9: San Pedro de Atacama | I9: Alto del Carmen | J9: Illapel | K9: Quintero | L9: Las Cabras | M9: Pencahue | N9: Penco | O9: El Carmen | P9: Gorbea | Q9: Los Lagos | R9: Llanquihue | S9: O'Higgins | T9: Porvenir | U9: Huechuraba
A10: 8 | C10: Huara | D10: Tamarugal | H10: Tocopilla | I10: Freirina | J10: Canela | K10: Villa Alemana | L10: Machalí | M10: Río Claro | N10: San Pedro de la Paz | O10: Ninhue | P10: Lautaro | Q10: Máfil | R10: Maullín | S10: Tortel | T10: Primavera | U10: Independencia
A11: 9 | C11: Pica | D11: Tamarugal | H11: María Elena | I11: Huasco | J11: Los Vilos | K11: Viña del Mar | L11: Malloa | M11: San Clemente | N11: Santa Juana | O11: Ñiquén | P11: Loncoche | Q11: Mariquina | R11: Puerto Varas | S11: Chile Chico | T11: Timaukel | U11: La Cisterna
A12: 10 | C12: Pozo Almonte | D12: Tamarugal | J12: Salamanca | K12: Isla de Pascua | L12: Mostazal | M12: San Rafael | N12: Talcahuano | O12: Pemuco | P12: Melipeuco | Q12: Paillaco | R12: Castro | S12: Río Ibáñez | T12: Natales | U12: La Florida
A13: 11 | C13: Alto Hospicio | D13: Iquique | J13: Ovalle | K13: Los Andes | L13: Olivar | M13: Cauquenes | N13: Tomé | O13: Pinto | P13: Nueva Imperial | Q13: Panguipulli | R13: Ancud | T13: Torres del Paine | U13: La Granja
A14: 12 | B14: Región de Antofagasta | C14: Antofagasta | D14: Antofagasta | J14: Combarbalá | K14: Calle Larga | L14: Peumo | M14: Chanco | N14: Hualpén | O14: Portezuelo | P14: Padre Las Casas | Q14: Río Bueno | R14: Chonchi | U14: La Pintana
A15: 13 | C15: Mejillones | D15: Antofagasta | J15: Monte Patria | K15: Rinconada | L15: Pichidegua | M15: Pelluhue | N15: Lebu | O15: Quillón | P15: Perquenco | R15: Curaco de Vélez | U15: La Reina
A16: 14 | C16: Sierra Gorda | D16: Antofagasta | J16: Punitaqui | K16: San Esteban | L16: Quinta de Tilcoco | M16: Curicó | N16: Arauco | O16: Quirihue | P16: Pitrufquén | R16: Dalcahue | U16: Las Condes
A17: 15 | C17: Taltal | D17: Antofagasta | J17: Río Hurtado | K17: La Ligua | L17: Rengo | M17: Hualañé | N17: Cañete | O17: Ránquil | P17: Pucón | R17: Puqueldón | U17: Lo Barnechea
A18: 16 | C18: Calama | D18: El Loa | K18: Cabildo | L18: Requínoa | M18: Licantén | N18: Contulmo | O18: San Carlos | P18: Saavedra | R18: Queilén | U18: Lo Espejo
A19: 17 | C19: Ollagüe | D19: El Loa | K19: Papudo | L19: San Vicente | M19: Molina | N19: Curanilahue | O19: San Fabián | P19: Teodoro Schmidt | R19: Quellón | U19: Lo Prado
A20: 18 | C20: San Pedro de Atacama | D20: El Loa | K20: Petorca | L20: Pichilemu | M20: Rauco | N20: Los Álamos | O20: San Ignacio | P20: Toltén | R20: Quemchi | U20: Macul
A21: 19 | C21: Tocopilla | D21: Tocopilla | K21: Zapallar | L21: La Estrella | M21: Romeral | N21: Tirúa | O21: San Nicolás | P21: Vilcún | R21: Quinchao | U21: Maipú
A22: 20 | C22: María Elena | D22: Tocopilla | K22: Quillota | L22: Litueche | M22: Sagrada Familia | N22: Los Ángeles | O22: Treguaco | P22: Villarrica | R22: Osorno | U22: Ñuñoa
A23: 21 | B23: Región de Atacama | C23: Copiapó | D23: Copiapó | K23: Calera | L23: Marchihue | M23: Teno | N23: Antuco | O23: Yungay | P23: Cholchol | R23: Puerto Octay | U23: Pedro Aguirre Cerda
A24: 22 | C24: Caldera | D24: Copiapó | K24: Hijuelas | L24: Navidad | M24: Vichuquén | N24: Cabrero | P24: Angol | R24: Purranque | U24: Peñalolén
A25: 23 | C25: Tierra Amarilla | D25: Copiapó | K25: La Cruz | L25: Paredones | M25: Linares | N25: Laja | P25: Collipulli | R25: Puyehue | U25: Providencia
A26: 24 | C26: Chañaral | D26: Chañaral | K26: Limache | L26: San Fernando | M26: Colbún | N26: Mulchén | P26: Curacautín | R26: Río Negro | U26: Pudahuel
A27: 25 | C27: Diego de Almagro | D27: Chañaral | K27: Nogales | L27: Chépica | M27: Longaví | N27: Nacimiento | P27: Ercilla | R27: San Juan de la Costa | U27: Quilicura
A28: 26 | C28: Vallenar | D28: Huasco | K28: Olmué | L28: Chimbarongo | M28: Parral | N28: Negrete | P28: Lonquimay | R28: San Pablo | U28: Quinta Normal
A29: 27 | C29: Alto del Carmen | D29: Huasco | K29: San Antonio | L29: Lolol | M29: Retiro | N29: Quilaco | P29: Los Sauces | R29: Chaitén | U29: Recoleta
A30: 28 | C30: Freirina | D30: Huasco | K30: Algarrobo | L30: Nancagua | M30: San Javier | N30: Quilleco | P30: Lumaco | R30: Futaleufú | U30: Renca
A31: 29 | C31: Huasco | D31: Huasco | K31: Cartagena | L31: Palmilla | M31: Villa Alegre | N31: San Rosendo | P31: Purén | R31: Hualaihué | U31: San Joaquín
A32: 30 | B32: Región de Coquimbo | C32: La Serena | D32: Elqui | K32: El Quisco | L32: Peralillo | M32: Yerbas Buenas | N32: Santa Bárbara | P32: Renaico | R32: Palena | U32: San Miguel
A33: 31 | C33: Coquimbo | D33: Elqui | K33: El Tabo | L33: Placilla | N33: Tucapel | P33: Traiguén | U33: San Ramón
A34: 32 | C34: Andacollo | D34: Elqui | K34: Santo Domingo | L34: Pumanque | N34: Yumbel | P34: Victoria | U34: Vitacura
A35: 33 | C35: La Higuera | D35: Elqui | K35: San Felipe | L35: Santa Cruz | N35: Alto Biobío | U35: Puente Alto
A36: 34 | C36: Paiguano | D36: Elqui | K36: Catemu | U36: Pirque
A37: 35 | C37: Vicuña | D37: Elqui | K37: Llaillay | U37: San José de Maipo
A38: 36 | C38: Illapel | D38: Choapa | K38: Panquehue | U38: Colina
A39: 37 | C39: Canela | D39: Choapa | K39: Putaendo | U39: Lampa
A40: 38 | C40: Los Vilos | D40: Choapa | K40: Santa María | U40: Tiltil
A41: 39 | C41: Salamanca | D41: Choapa | U41: San Bernardo
...
